Workbook

Sheet 参数与说明
A1: USDA 美国畜牧·饲料价格 — 历史趋势
A2: 数据来源：USDA NASS Quick Stats（价格收到价 Price Received，全国 SURVEY）
A3: 来源接口：https://quickstats.nass.usda.gov/api/ | 导出日期：2026-10-14
A5: 可调参数
A6: 美元兑人民币汇率 | B6: 6.77 | C6: 改这里→所有Sheet的「元/公斤」列自动重算。来源：运行参数 FX_USD_CNY=6.77，仅作换算口径。
A8: 单位换算系数（每单位含多少公斤）
A9: cwt(英担) | B9: 45.3592 kg | C9: 牛/猪/奶：$/cwt ÷45.3592 ×汇率 = 元/公斤
A10: lb(磅) | B10: 0.453592 kg | C10: 鸡肉：$/lb ÷0.453592 ×汇率 = 元/公斤
A11: bu 玉米 | B11: 25.4012 kg | C11: 玉米：$/bu ÷25.4012 ×汇率 = 元/公斤
A12: bu 大豆 | B12: 27.2155 kg | C12: 大豆：$/bu ÷27.2155 ×汇率 = 元/公斤
A13: 打(鸡蛋) | B13: ≈0.68 kg | C13: 鸡蛋：$/打 ÷0.68 ×汇率 = 元/公斤（含壳近似，仅参考）
A15: 口径与解读提示（重要）
A16: 1) 这是美国「农场出售端价格收到价」(monthly)，对应中国农业农村部的产业链上游/农场价，不是县集贸市场零售价；与中国零售口径不完全可比。
A17: 2) 各Sheet「趋势图」用美制原值绘制（真实历史）。
A18: 3) 「元/公斤」列用当前汇率统一换算，仅为与中国现价对比；历史早期行不代表当年实际人民币价格（汇率/币值已大不同），勿据此读历史人民币走势。
A19: 4) 环比=与上月比，同比=与去年同月比，按日期精确匹配（缺月自动留空）。
A20: 5) boxed beef分割肉批发价、屠宰量/胴重等NASS无，需USDA市场新闻(MMN)补。
A21: 6) 已剔除PCT OF PARITY(平价百分比)及$/HEAD等非价格口径，只保留$/单位价格。
A24: 各Sheet概览
A25: 品类 | B25: 月度行数 | C25: 时间范围 / 主指标
A26: 牛肉·活牛 | B26: 1405 | C26: 1909-08 ~ 2026-08 | 主:肉牛(≥500磅,≈活牛)
A27: 生猪 | B27: 1405 | C27: 1909-08 ~ 2026-08 | 主:生猪(全部)
A28: 生鲜乳 | B28: 560 | C28: 1980-01 ~ 2026-08 | 主:生鲜乳(全部)
A29: 鸡蛋 | B29: 333 | C29: 1998-12 ~ 2026-08 | 主:鸡蛋(全部)
A30: 鸡肉 | B30: 428 | C30: 1991-01 ~ 2026-08 | 主:肉鸡(Broilers)
A31: 玉米 | B31: 1424 | C31: 1908-01 ~ 2026-08 | 主:玉米(Corn grain)
A32: 大豆 | B32: 1286 | C32: 1913-10 ~ 2026-08 | 主:大豆(Soybeans)

Sheet 牛肉·活牛
A1: 牛肉·活牛 — USDA NASS 价格收到价（月度）
A2: 美元/英担(cwt=100磅)；元/公斤=主指标×汇率('参数与说明'!$B$6)÷45.3592。趋势图用美制原值。
A4: 日期 | B4: 年 | C4: 月 | D4: 肉牛(≥500磅,≈活牛) ($ / CWT) | E4: 阉公牛及小母牛(≥500磅) ($ / CWT) | F4: 犊牛(Calves) ($ / CWT) | G4: 母牛(Cows) ($ / CWT) | H4: 主指标(元/公斤) | I4: 环比% | J4: 同比%
A5: 3501 | B5: 1909 | C5: 8 | D5: 5.41 | F5: 6.6 | H5: =IF(D5="","",D5*'参数与说明'!$B$6/45.3592) | I5: =IFERROR(IF(D5="","",D5/INDEX($D:$D,MATCH(EDATE($A5,-1),$A:$A,0))-1),"") | J5: =IFERROR(IF(D5="","",D5/INDEX($D:$D,MATCH(EDATE($A5,-12),$A:$A,0))-1),"")
A6: 3532 | B6: 1909 | C6: 9 | D6: 5.49 | F6: 6.73 | H6: =IF(D6="","",D6*'参数与说明'!$B$6/45.3592) | I6: =IFERROR(IF(D6="","",D6/INDEX($D:$D,MATCH(EDATE($A6,-1),$A:$A,0))-1),"") | J6: =IFERROR(IF(D6="","",D6/INDEX($D:$D,MATCH(EDATE($A6,-12),$A:$A,0))-1),"")
A7: 3562 | B7: 1909 | C7: 10 | D7: 5.36 | F7: 6.94 | H7: =IF(D7="","",D7*'参数与说明'!$B$6/45.3592) | I7: =IFERROR(IF(D7="","",D7/INDEX($D:$D,MATCH(EDATE($A7,-1),$A:$A,0))-1),"") | J7: =IFERROR(IF(D7="","",D7/INDEX($D:$D,MATCH(EDATE($A7,-12),$A:$A,0))-1),"")
A8: 3593 | B8: 1909 | C8: 11 | D8: 5.19 | F8: 6.72 | H8: =IF(D8="","",D8*'参数与说明'!$B$6/45.3592) | I8: =IFERROR(IF(D8="","",D8/INDEX($D:$D,MATCH(EDATE($A8,-1),$A:$A,0))-1),"") | J8: =IFERROR(IF(D8="","",D8/INDEX($D:$D,MATCH(EDATE($A8,-12),$A:$A,0))-1),"")
A9: 3623 | B9: 1909 | C9: 12 | D9: 5.05 | F9: 6.71 | H9: =IF(D9="","",D9*'参数与说明'!$B$6/45.3592) | I9: =IFERROR(IF(D9="","",D9/INDEX($D:$D,MATCH(EDATE($A9,-1),$A:$A,0))-1),"") | J9: =IFERROR(IF(D9="","",D9/INDEX($D:$D,MATCH(EDATE($A9,-12),$A:$A,0))-1),"")
A10: 3654 | B10: 1910 | C10: 1 | D10: 4.78 | F10: 6.43 | H10: =IF(D10="","",D10*'参数与说明'!$B$6/45.3592) | I10: =IFERROR(IF(D10="","",D10/INDEX($D:$D,MATCH(EDATE($A10,-1),$A:$A,0))-1),"") | J10: =IFERROR(IF(D10="","",D10/INDEX($D:$D,MATCH(EDATE($A10,-12),$A:$A,0))-1),"")
A11: 3685 | B11: 1910 | C11: 2 | D11: 4.73 | F11: 6.21 | H11: =IF(D11="","",D11*'参数与说明'!$B$6/45.3592) | I11: =IFERROR(IF(D11="","",D11/INDEX($D:$D,MATCH(EDATE($A11,-1),$A:$A,0))-1),"") | J11: =IFERROR(IF(D11="","",D11/INDEX($D:$D,MATCH(EDATE($A11,-12),$A:$A,0))-1),"")
A12: 3713 | B12: 1910 | C12: 3 | D12: 5.06 | F12: 6.53 | H12: =IF(D12="","",D12*'参数与说明'!$B$6/45.3592) | I12: =IFERROR(IF(D12="","",D12/INDEX($D:$D,MATCH(EDATE($A12,-1),$A:$A,0))-1),"") | J12: =IFERROR(IF(D12="","",D12/INDEX($D:$D,MATCH(EDATE($A12,-12),$A:$A,0))-1),"")
A13: 3744 | B13: 1910 | C13: 4 | D13: 5.46 | F13: 6.57 | H13: =IF(D13="","",D13*'参数与说明'!$B$6/45.3592) | I13: =IFERROR(IF(D13="","",D13/INDEX($D:$D,MATCH(EDATE($A13,-1),$A:$A,0))-1),"") | J13: =IFERROR(IF(D13="","",D13/INDEX($D:$D,MATCH(EDATE($A13,-12),$A:$A,0))-1),"")
A14: 3774 | B14: 1910 | C14: 5 | D14: 5.32 | F14: 6.36 | H14: =IF(D14="","",D14*'参数与说明'!$B$6/45.3592) | I14: =IFERROR(IF(D14="","",D14/INDEX($D:$D,MATCH(EDATE($A14,-1),$A:$A,0))-1),"") | J14: =IFERROR(IF(D14="","",D14/INDEX($D:$D,MATCH(EDATE($A14,-12),$A:$A,0))-1),"")
A15: 3805 | B15: 1910 | C15: 6 | D15: 5.31 | F15: 6.54 | H15: =IF(D15="","",D15*'参数与说明'!$B$6/45.3592) | I15: =IFERROR(IF(D15="","",D15/INDEX($D:$D,MATCH(EDATE($A15,-1),$A:$A,0))-1),"") | J15: =IFERROR(IF(D15="","",D15/INDEX($D:$D,MATCH(EDATE($A15,-12),$A:$A,0))-1),"")
A16: 3835 | B16: 1910 | C16: 7 | D16: 4.93 | F16: 6.39 | H16: =IF(D16="","",D16*'参数与说明'!$B$6/45.3592) | I16: =IFERROR(IF(D16="","",D16/INDEX($D:$D,MATCH(EDATE($A16,-1),$A:$A,0))-1),"") | J16: =IFERROR(IF(D16="","",D16/INDEX($D:$D,MATCH(EDATE($A16,-12),$A:$A,0))-1),"")
... A525: 19329 | B525: 1952 | C525: 12 | D525: 19 | F525: 20.5 | H525: =IF(D525="","",D525*'参数与说明'!$B$6/45.3592) | I525: =IFERROR(IF(D525="","",D525/INDEX($D:$D,MATCH(EDATE($A525,-1),$A:$A,0))-1),"") | J525: =IFERROR(IF(D525="","",D525/INDEX($D:$D,MATCH(EDATE($A525,-12),$A:$A,0))-1),"")
A526: 19360 | B526: 1953 | C526: 1 | D526: 19.1 | E526: 21.9 | F526: 22.1 | G526: 13.7 | H526: =IF(D526="","",D526*'参数与说明'!$B$6/45.3592) | I526: =IFERROR(IF(D526="","",D526/INDEX($D:$D,MATCH(EDATE($A526,-1),$A:$A,0))-1),"") | J526: =IFERROR(IF(D526="","",D526/INDEX($D:$D,MATCH(EDATE($A526,-12),$A:$A,0))-1),"")
A527: 19391 | B527: 1953 | C527: 2 | D527: 18.5 | E527: 20.7 | F527: 22.1 | G527: 13.5 | H527: =IF(D527="","",D527*'参数与说明'!$B$6/45.3592) | I527: =IFERROR(IF(D527="","",D527/INDEX($D:$D,MATCH(EDATE($A527,-1),$A:$A,0))-1),"") | J527: =IFERROR(IF(D527="","",D527/INDEX($D:$D,MATCH(EDATE($A527,-12),$A:$A,0))-1),"")
A528: 19419 | B528: 1953 | C528: 3 | D528: 17.7 | E528: 19.6 | F528: 20.1 | G528: 13.1 | H528: =IF(D528="","",D528*'参数与说明'!$B$6/45.3592) | I528: =IFERROR(IF(D528="","",D528/INDEX($D:$D,MATCH(EDATE($A528,-1),$A:$A,0))-1),"") | J528: =IFERROR(IF(D528="","",D528/INDEX($D:$D,MATCH(EDATE($A528,-12),$A:$A,0))-1),"")
A529: 19450 | B529: 1953 | C529: 4 | D529: 17.3 | E529: 19.1 | F529: 19.3 | G529: 12.5 | H529: =IF(D529="","",D529*'参数与说明'!$B$6/45.3592) | I529: =IFERROR(IF(D529="","",D529/INDEX($D:$D,MATCH(EDATE($A529,-1),$A:$A,0))-1),"") | J529: =IFERROR(IF(D529="","",D529/INDEX($D:$D,MATCH(EDATE($A529,-12),$A:$A,0))-1),"")
A530: 19480 | B530: 1953 | C530: 5 | D530: 17.5 | E530: 19.3 | F530: 19.4 | G530: 12.4 | H530: =IF(D530="","",D530*'参数与说明'!$B$6/45.3592) | I530: =IFERROR(IF(D530="","",D530/INDEX($D:$D,MATCH(EDATE($A530,-1),$A:$A,0))-1),"") | J530: =IFERROR(IF(D530="","",D530/INDEX($D:$D,MATCH(EDATE($A530,-12),$A:$A,0))-1),"")
A531: 19511 | B531: 1953 | C531: 6 | D531: 16 | E531: 18.1 | F531: 16.5 | G531: 10.7 | H531: =IF(D531="","",D531*'参数与说明'!$B$6/45.3592) | I531: =IFERROR(IF(D531="","",D531/INDEX($D:$D,MATCH(EDATE($A531,-1),$A:$A,0))-1),"") | J531: =IFERROR(IF(D531="","",D531/INDEX($D:$D,MATCH(EDATE($A531,-12),$A:$A,0))-1),"")
A532: 19541 | B532: 1953 | C532: 7 | D532: 17.1 | E532: 19.6 | F532: 16.8 | G532: 11.5 | H532: =IF(D532="","",D532*'参数与说明'!$B$6/45.3592) | I532: =IFERROR(IF(D532="","",D532/INDEX($D:$D,MATCH(EDATE($A532,-1),$A:$A,0))-1),"") | J532: =IFERROR(IF(D532="","",D532/INDEX($D:$D,MATCH(EDATE($A532,-12),$A:$A,0))-1),"")
A533: 19572 | B533: 1953 | C533: 8 | D533: 16.1 | E533: 18.6 | F533: 16.1 | G533: 10.3 | H533: =IF(D533="","",D533*'参数与说明'!$B$6/45.3592) | I533: =IFERROR(IF(D533="","",D533/INDEX($D:$D,MATCH(EDATE($A533,-1),$A:$A,0))-1),"") | J533: =IFERROR(IF(D533="","",D533/INDEX($D:$D,MATCH(EDATE($A533,-12),$A:$A,0))-1),"")
A534: 19603 | B534: 1953 | C534: 9 | D534: 15.6 | E534: 18.1 | F534: 14.8 | G534: 9.9 | H534: =IF(D534="","",D534*'参数与说明'!$B$6/45.3592) | I534: =IFERROR(IF(D534="","",D534/INDEX($D:$D,MATCH(EDATE($A534,-1),$A:$A,0))-1),"") | J534: =IFERROR(IF(D534="","",D534/INDEX($D:$D,MATCH(EDATE($A534,-12),$A:$A,0))-1),"")
A535: 19633 | B535: 1953 | C535: 10 | D535: 14.6 | E535: 17.1 | F535: 13.8 | G535: 9.2 | H535: =IF(D535="","",D535*'参数与说明'!$B$6/45.3592) | I535: =IFERROR(IF(D535="","",D535/INDEX($D:$D,MATCH(EDATE($A535,-1),$A:$A,0))-1),"") | J535: =IFERROR(IF(D535="","",D535/INDEX($D:$D,MATCH(EDATE($A535,-12),$A:$A,0))-1),"")
A536: 19664 | B536: 1953 | C536: 11 | D536: 14.5 | E536: 17.5 | F536: 14.5 | G536: 9 | H536: =IF(D536="","",D536*'参数与说明'!$B$6/45.3592) | I536: =IFERROR(IF(D536="","",D536/INDEX($D:$D,MATCH(EDATE($A536,-1),$A:$A,0))-1),"") | J536: =IFERROR(IF(D536="","",D536/INDEX($D:$D,MATCH(EDATE($A536,-12),$A:$A,0))-1),"")
A537: 19694 | B537: 1953 | C537: 12 | D537: 14.8 | E537: 17.8 | F537: 15.6 | G537: 9.3 | H537: =IF(D537="","",D537*'参数与说明'!$B$6/45.3592) | I537: =IFERROR(IF(D537="","",D537/INDEX($D:$D,MATCH(EDATE($A537,-1),$A:$A,0))-1),"") | J537: =IFERROR(IF(D537="","",D537/INDEX($D:$D,MATCH(EDATE($A537,-12),$A:$A,0))-1),"")
... A1409: 46235 | B1409: 2026 | C1409: 8 | D1409: 231 | E1409: 234 | F1409: 455 | G1409: 172 | H1409: =IF(D1409="","",D1409*'参数与说明'!$B$6/45.3592) | I1409: =IFERROR(IF(D1409="","",D1409/INDEX($D:$D,MATCH(EDATE($A1409,-1),$A:$A,0))-1),"") | J1409: =IFERROR(IF(D1409="","",D1409/INDEX($D:$D,MATCH(EDATE($A1409,-12),$A:$A,0))-1),"")

Sheet 生猪
A1: 生猪 — USDA NASS 价格收到价（月度）
A2: 美元/英担(cwt=100磅)；元/公斤=主指标×汇率('参数与说明'!$B$6)÷45.3592。趋势图用美制原值。
A4: 日期 | B4: 年 | C4: 月 | D4: 生猪(全部) ($ / CWT) | E4: 阉公猪及后备母猪(育肥猪) ($ / CWT) | F4: 母猪(Sows) ($ / CWT) | G4: 主指标(元/公斤) | H4: 环比% | I4: 同比%
A5: 3501 | B5: 1909 | C5: 8 | D5: 6.97 | G5: =IF(D5="","",D5*'参数与说明'!$B$6/45.3592) | H5: =IFERROR(IF(D5="","",D5/INDEX($D:$D,MATCH(EDATE($A5,-1),$A:$A,0))-1),"") | I5: =IFERROR(IF(D5="","",D5/INDEX($D:$D,MATCH(EDATE($A5,-12),$A:$A,0))-1),"")
A6: 3532 | B6: 1909 | C6: 9 | D6: 7.18 | G6: =IF(D6="","",D6*'参数与说明'!$B$6/45.3592) | H6: =IFERROR(IF(D6="","",D6/INDEX($D:$D,MATCH(EDATE($A6,-1),$A:$A,0))-1),"") | I6: =IFERROR(IF(D6="","",D6/INDEX($D:$D,MATCH(EDATE($A6,-12),$A:$A,0))-1),"")
A7: 3562 | B7: 1909 | C7: 10 | D7: 7.04 | G7: =IF(D7="","",D7*'参数与说明'!$B$6/45.3592) | H7: =IFERROR(IF(D7="","",D7/INDEX($D:$D,MATCH(EDATE($A7,-1),$A:$A,0))-1),"") | I7: =IFERROR(IF(D7="","",D7/INDEX($D:$D,MATCH(EDATE($A7,-12),$A:$A,0))-1),"")
A8: 3593 | B8: 1909 | C8: 11 | D8: 7.23 | G8: =IF(D8="","",D8*'参数与说明'!$B$6/45.3592) | H8: =IFERROR(IF(D8="","",D8/INDEX($D:$D,MATCH(EDATE($A8,-1),$A:$A,0))-1),"") | I8: =IFERROR(IF(D8="","",D8/INDEX($D:$D,MATCH(EDATE($A8,-12),$A:$A,0))-1),"")
A9: 3623 | B9: 1909 | C9: 12 | D9: 7.54 | G9: =IF(D9="","",D9*'参数与说明'!$B$6/45.3592) | H9: =IFERROR(IF(D9="","",D9/INDEX($D:$D,MATCH(EDATE($A9,-1),$A:$A,0))-1),"") | I9: =IFERROR(IF(D9="","",D9/INDEX($D:$D,MATCH(EDATE($A9,-12),$A:$A,0))-1),"")
A10: 3654 | B10: 1910 | C10: 1 | D10: 7.84 | G10: =IF(D10="","",D10*'参数与说明'!$B$6/45.3592) | H10: =IFERROR(IF(D10="","",D10/INDEX($D:$D,MATCH(EDATE($A10,-1),$A:$A,0))-1),"") | I10: =IFERROR(IF(D10="","",D10/INDEX($D:$D,MATCH(EDATE($A10,-12),$A:$A,0))-1),"")
A11: 3685 | B11: 1910 | C11: 2 | D11: 7.97 | G11: =IF(D11="","",D11*'参数与说明'!$B$6/45.3592) | H11: =IFERROR(IF(D11="","",D11/INDEX($D:$D,MATCH(EDATE($A11,-1),$A:$A,0))-1),"") | I11: =IFERROR(IF(D11="","",D11/INDEX($D:$D,MATCH(EDATE($A11,-12),$A:$A,0))-1),"")
A12: 3713 | B12: 1910 | C12: 3 | D12: 9.29 | G12: =IF(D12="","",D12*'参数与说明'!$B$6/45.3592) | H12: =IFERROR(IF(D12="","",D12/INDEX($D:$D,MATCH(EDATE($A12,-1),$A:$A,0))-1),"") | I12: =IFERROR(IF(D12="","",D12/INDEX($D:$D,MATCH(EDATE($A12,-12),$A:$A,0))-1),"")
A13: 3744 | B13: 1910 | C13: 4 | D13: 9.44 | G13: =IF(D13="","",D13*'参数与说明'!$B$6/45.3592) | H13: =IFERROR(IF(D13="","",D13/INDEX($D:$D,MATCH(EDATE($A13,-1),$A:$A,0))-1),"") | I13: =IFERROR(IF(D13="","",D13/INDEX($D:$D,MATCH(EDATE($A13,-12),$A:$A,0))-1),"")
A14: 3774 | B14: 1910 | C14: 5 | D14: 8.65 | G14: =IF(D14="","",D14*'参数与说明'!$B$6/45.3592) | H14: =IFERROR(IF(D14="","",D14/INDEX($D:$D,MATCH(EDATE($A14,-1),$A:$A,0))-1),"") | I14: =IFERROR(IF(D14="","",D14/INDEX($D:$D,MATCH(EDATE($A14,-12),$A:$A,0))-1),"")
A15: 3805 | B15: 1910 | C15: 6 | D15: 8.65 | G15: =IF(D15="","",D15*'参数与说明'!$B$6/45.3592) | H15: =IFERROR(IF(D15="","",D15/INDEX($D:$D,MATCH(EDATE($A15,-1),$A:$A,0))-1),"") | I15: =IFERROR(IF(D15="","",D15/INDEX($D:$D,MATCH(EDATE($A15,-12),$A:$A,0))-1),"")
A16: 3835 | B16: 1910 | C16: 7 | D16: 8.2 | G16: =IF(D16="","",D16*'参数与说明'!$B$6/45.3592) | H16: =IFERROR(IF(D16="","",D16/INDEX($D:$D,MATCH(EDATE($A16,-1),$A:$A,0))-1),"") | I16: =IFERROR(IF(D16="","",D16/INDEX($D:$D,MATCH(EDATE($A16,-12),$A:$A,0))-1),"")
... A861: 29556 | B861: 1980 | C861: 12 | D861: 43.8 | G861: =IF(D861="","",D861*'参数与说明'!$B$6/45.3592) | H861: =IFERROR(IF(D861="","",D861/INDEX($D:$D,MATCH(EDATE($A861,-1),$A:$A,0))-1),"") | I861: =IFERROR(IF(D861="","",D861/INDEX($D:$D,MATCH(EDATE($A861,-12),$A:$A,0))-1),"")
A862: 29587 | B862: 1981 | C862: 1 | D862: 40.9 | F862: 37.4 | G862: =IF(D862="","",D862*'参数与说明'!$B$6/45.3592) | H862: =IFERROR(IF(D862="","",D862/INDEX($D:$D,MATCH(EDATE($A862,-1),$A:$A,0))-1),"") | I862: =IFERROR(IF(D862="","",D862/INDEX($D:$D,MATCH(EDATE($A862,-12),$A:$A,0))-1),"")
A863: 29618 | B863: 1981 | C863: 2 | D863: 41.3 | F863: 37.6 | G863: =IF(D863="","",D863*'参数与说明'!$B$6/45.3592) | H863: =IFERROR(IF(D863="","",D863/INDEX($D:$D,MATCH(EDATE($A863,-1),$A:$A,0))-1),"") | I863: =IFERROR(IF(D863="","",D863/INDEX($D:$D,MATCH(EDATE($A863,-12),$A:$A,0))-1),"")
A864: 29646 | B864: 1981 | C864: 3 | D864: 38.8 | F864: 35.8 | G864: =IF(D864="","",D864*'参数与说明'!$B$6/45.3592) | H864: =IFERROR(IF(D864="","",D864/INDEX($D:$D,MATCH(EDATE($A864,-1),$A:$A,0))-1),"") | I864: =IFERROR(IF(D864="","",D864/INDEX($D:$D,MATCH(EDATE($A864,-12),$A:$A,0))-1),"")
A865: 29677 | B865: 1981 | C865: 4 | D865: 39 | F865: 35.6 | G865: =IF(D865="","",D865*'参数与说明'!$B$6/45.3592) | H865: =IFERROR(IF(D865="","",D865/INDEX($D:$D,MATCH(EDATE($A865,-1),$A:$A,0))-1),"") | I865: =IFERROR(IF(D865="","",D865/INDEX($D:$D,MATCH(EDATE($A865,-12),$A:$A,0))-1),"")
A866: 29707 | B866: 1981 | C866: 5 | D866: 40.9 | F866: 36.4 | G866: =IF(D866="","",D866*'参数与说明'!$B$6/45.3592) | H866: =IFERROR(IF(D866="","",D866/INDEX($D:$D,MATCH(EDATE($A866,-1),$A:$A,0))-1),"") | I866: =IFERROR(IF(D866="","",D866/INDEX($D:$D,MATCH(EDATE($A866,-12),$A:$A,0))-1),"")
A867: 29738 | B867: 1981 | C867: 6 | D867: 47.4 | F867: 41.9 | G867: =IF(D867="","",D867*'参数与说明'!$B$6/45.3592) | H867: =IFERROR(IF(D867="","",D867/INDEX($D:$D,MATCH(EDATE($A867,-1),$A:$A,0))-1),"") | I867: =IFERROR(IF(D867="","",D867/INDEX($D:$D,MATCH(EDATE($A867,-12),$A:$A,0))-1),"")
A868: 29768 | B868: 1981 | C868: 7 | D868: 49.3 | F868: 43.4 | G868: =IF(D868="","",D868*'参数与说明'!$B$6/45.3592) | H868: =IFERROR(IF(D868="","",D868/INDEX($D:$D,MATCH(EDATE($A868,-1),$A:$A,0))-1),"") | I868: =IFERROR(IF(D868="","",D868/INDEX($D:$D,MATCH(EDATE($A868,-12),$A:$A,0))-1),"")
A869: 29799 | B869: 1981 | C869: 8 | D869: 49.2 | F869: 43.7 | G869: =IF(D869="","",D869*'参数与说明'!$B$6/45.3592) | H869: =IFERROR(IF(D869="","",D869/INDEX($D:$D,MATCH(EDATE($A869,-1),$A:$A,0))-1),"") | I869: =IFERROR(IF(D869="","",D869/INDEX($D:$D,MATCH(EDATE($A869,-12),$A:$A,0))-1),"")
A870: 29830 | B870: 1981 | C870: 9 | D870: 48.6 | F870: 45.2 | G870: =IF(D870="","",D870*'参数与说明'!$B$6/45.3592) | H870: =IFERROR(IF(D870="","",D870/INDEX($D:$D,MATCH(EDATE($A870,-1),$A:$A,0))-1),"") | I870: =IFERROR(IF(D870="","",D870/INDEX($D:$D,MATCH(EDATE($A870,-12),$A:$A,0))-1),"")
A871: 29860 | B871: 1981 | C871: 10 | D871: 45 | F871: 42 | G871: =IF(D871="","",D871*'参数与说明'!$B$6/45.3592) | H871: =IFERROR(IF(D871="","",D871/INDEX($D:$D,MATCH(EDATE($A871,-1),$A:$A,0))-1),"") | I871: =IFERROR(IF(D871="","",D871/INDEX($D:$D,MATCH(EDATE($A871,-12),$A:$A,0))-1),"")
A872: 29891 | B872: 1981 | C872: 11 | D872: 41.5 | F872: 37.8 | G872: =IF(D872="","",D872*'参数与说明'!$B$6/45.3592) | H872: =IFERROR(IF(D872="","",D872/INDEX($D:$D,MATCH(EDATE($A872,-1),$A:$A,0))-1),"") | I872: =IFERROR(IF(D872="","",D872/INDEX($D:$D,MATCH(EDATE($A872,-12),$A:$A,0))-1),"")
A873: 29921 | B873: 1981 | C873: 12 | D873: 39 | F873: 33.2 | G873: =IF(D873="","",D873*'参数与说明'!$B$6/45.3592) | H873: =IFERROR(IF(D873="","",D873/INDEX($D:$D,MATCH(EDATE($A873,-1),$A:$A,0))-1),"") | I873: =IFERROR(IF(D873="","",D873/INDEX($D:$D,MATCH(EDATE($A873,-12),$A:$A,0))-1),"")
... A993: 33573 | B993: 1991 | C993: 12 | D993: 38.6 | F993: 27.9 | G993: =IF(D993="","",D993*'参数与说明'!$B$6/45.3592) | H993: =IFERROR(IF(D993="","",D993/INDEX($D:$D,MATCH(EDATE($A993,-1),$A:$A,0))-1),"") | I993: =IFERROR(IF(D993="","",D993/INDEX($D:$D,MATCH(EDATE($A993,-12),$A:$A,0))-1),"")
A994: 33604 | B994: 1992 | C994: 1 | D994: 36.8 | E994: 37.6 | F994: 27.1 | G994: =IF(D994="","",D994*'参数与说明'!$B$6/45.3592) | H994: =IFERROR(IF(D994="","",D994/INDEX($D:$D,MATCH(EDATE($A994,-1),$A:$A,0))-1),"") | I994: =IFERROR(IF(D994="","",D994/INDEX($D:$D,MATCH(EDATE($A994,-12),$A:$A,0))-1),"")
A995: 33635 | B995: 1992 | C995: 2 | D995: 40.2 | E995: 40.8 | F995: 31.1 | G995: =IF(D995="","",D995*'参数与说明'!$B$6/45.3592) | H995: =IFERROR(IF(D995="","",D995/INDEX($D:$D,MATCH(EDATE($A995,-1),$A:$A,0))-1),"") | I995: =IFERROR(IF(D995="","",D995/INDEX($D:$D,MATCH(EDATE($A995,-12),$A:$A,0))-1),"")
A996: 33664 | B996: 1992 | C996: 3 | D996: 39.1 | E996: 39.5 | F996: 32.9 | G996: =IF(D996="","",D996*'参数与说明'!$B$6/45.3592) | H996: =IFERROR(IF(D996="","",D996/INDEX($D:$D,MATCH(EDATE($A996,-1),$A:$A,0))-1),"") | I996: =IFERROR(IF(D996="","",D996/INDEX($D:$D,MATCH(EDATE($A996,-12),$A:$A,0))-1),"")
A997: 33695 | B997: 1992 | C997: 4 | D997: 41 | E997: 41.5 | F997: 34.2 | G997: =IF(D997="","",D997*'参数与说明'!$B$6/45.3592) | H997: =IFERROR(IF(D997="","",D997/INDEX($D:$D,MATCH(EDATE($A997,-1),$A:$A,0))-1),"") | I997: =IFERROR(IF(D997="","",D997/INDEX($D:$D,MATCH(EDATE($A997,-12),$A:$A,0))-1),"")
A998: 33725 | B998: 1992 | C998: 5 | D998: 45.1 | E998: 45.6 | F998: 36.5 | G998: =IF(D998="","",D998*'参数与说明'!$B$6/45.3592) | H998: =IFERROR(IF(D998="","",D998/INDEX($D:$D,MATCH(EDATE($A998,-1),$A:$A,0))-1),"") | I998: =IFERROR(IF(D998="","",D998/INDEX($D:$D,MATCH(EDATE($A998,-12),$A:$A,0))-1),"")
A999: 33756 | B999: 1992 | C999: 6 | D999: 46.7 | E999: 47.7 | F999: 34.9 | G999: =IF(D999="","",D999*'参数与说明'!$B$6/45.3592) | H999: =IFERROR(IF(D999="","",D999/INDEX($D:$D,MATCH(EDATE($A999,-1),$A:$A,0))-1),"") | I999: =IFERROR(IF(D999="","",D999/INDEX($D:$D,MATCH(EDATE($A999,-12),$A:$A,0))-1),"")
A1000: 33786 | B1000: 1992 | C1000: 7 | D1000: 44.6 | E1000: 45.8 | F1000: 32 | G1000: =IF(D1000="","",D1000*'参数与说明'!$B$6/45.3592) | H1000: =IFERROR(IF(D1000="","",D1000/INDEX($D:$D,MATCH(EDATE($A1000,-1),$A:$A,0))-1),"") | I1000: =IFERROR(IF(D1000="","",D1000/INDEX($D:$D,MATCH(EDATE($A1000,-12),$A:$A,0))-1),"")
A1001: 33817 | B1001: 1992 | C1001: 8 | D1001: 44.1 | E1001: 45 | F1001: 33.4 | G1001: =IF(D1001="","",D1001*'参数与说明'!$B$6/45.3592) | H1001: =IFERROR(IF(D1001="","",D1001/INDEX($D:$D,MATCH(EDATE($A1001,-1),$A:$A,0))-1),"") | I1001: =IFERROR(IF(D1001="","",D1001/INDEX($D:$D,MATCH(EDATE($A1001,-12),$A:$A,0))-1),"")
A1002: 33848 | B1002: 1992 | C1002: 9 | D1002: 42.1 | E1002: 42.8 | F1002: 32.1 | G1002: =IF(D1002="","",D1002*'参数与说明'!$B$6/45.3592) | H1002: =IFERROR(IF(D1002="","",D1002/INDEX($D:$D,MATCH(EDATE($A1002,-1),$A:$A,0))-1),"") | I1002: =IFERROR(IF(D1002="","",D1002/INDEX($D:$D,MATCH(EDATE($A1002,-12),$A:$A,0))-1),"")
A1003: 33878 | B1003: 1992 | C1003: 10 | D1003: 42 | E1003: 42.5 | F1003: 35.5 | G1003: =IF(D1003="","",D1003*'参数与说明'!$B$6/45.3592) | H1003: =IFERROR(IF(D1003="","",D1003/INDEX($D:$D,MATCH(EDATE($A1003,-1),$A:$A,0))-1),"") | I1003: =IFERROR(IF(D1003="","",D1003/INDEX($D:$D,MATCH(EDATE($A1003,-12),$A:$A,0))-1),"")
A1004: 33909 | B1004: 1992 | C1004: 11 | D1004: 41.1 | E1004: 41.7 | F1004: 32.2 | G1004: =IF(D1004="","",D1004*'参数与说明'!$B$6/45.3592) | H1004: =IFERROR(IF(D1004="","",D1004/INDEX($D:$D,MATCH(EDATE($A1004,-1),$A:$A,0))-1),"") | I1004: =IFERROR(IF(D1004="","",D1004/INDEX($D:$D,MATCH(EDATE($A1004,-12),$A:$A,0))-1),"")
...

Sheet 生鲜乳
A1: 生鲜乳 — USDA NASS 价格收到价（月度）
A2: 美元/英担(cwt=100磅)；元/公斤=主指标×汇率('参数与说明'!$B$6)÷45.3592。趋势图用美制原值。
A4: 日期 | B4: 年 | C4: 月 | D4: 生鲜乳(全部) ($ / CWT) | E4: 饮用级(Fluid grade) ($ / CWT) | F4: 制造级(Manufacturing) ($ / CWT) | G4: 主指标(元/公斤) | H4: 环比% | I4: 同比%
A5: 29221 | B5: 1980 | C5: 1 | D5: 12.8 | E5: 13 | F5: 11.7 | G5: =IF(D5="","",D5*'参数与说明'!$B$6/45.3592) | H5: =IFERROR(IF(D5="","",D5/INDEX($D:$D,MATCH(EDATE($A5,-1),$A:$A,0))-1),"") | I5: =IFERROR(IF(D5="","",D5/INDEX($D:$D,MATCH(EDATE($A5,-12),$A:$A,0))-1),"")
A6: 29252 | B6: 1980 | C6: 2 | D6: 12.8 | E6: 13 | F6: 11.7 | G6: =IF(D6="","",D6*'参数与说明'!$B$6/45.3592) | H6: =IFERROR(IF(D6="","",D6/INDEX($D:$D,MATCH(EDATE($A6,-1),$A:$A,0))-1),"") | I6: =IFERROR(IF(D6="","",D6/INDEX($D:$D,MATCH(EDATE($A6,-12),$A:$A,0))-1),"")
A7: 29281 | B7: 1980 | C7: 3 | D7: 12.8 | E7: 12.9 | F7: 11.8 | G7: =IF(D7="","",D7*'参数与说明'!$B$6/45.3592) | H7: =IFERROR(IF(D7="","",D7/INDEX($D:$D,MATCH(EDATE($A7,-1),$A:$A,0))-1),"") | I7: =IFERROR(IF(D7="","",D7/INDEX($D:$D,MATCH(EDATE($A7,-12),$A:$A,0))-1),"")
A8: 29312 | B8: 1980 | C8: 4 | D8: 12.7 | E8: 12.8 | F8: 11.8 | G8: =IF(D8="","",D8*'参数与说明'!$B$6/45.3592) | H8: =IFERROR(IF(D8="","",D8/INDEX($D:$D,MATCH(EDATE($A8,-1),$A:$A,0))-1),"") | I8: =IFERROR(IF(D8="","",D8/INDEX($D:$D,MATCH(EDATE($A8,-12),$A:$A,0))-1),"")
A9: 29342 | B9: 1980 | C9: 5 | D9: 12.6 | E9: 12.7 | F9: 11.7 | G9: =IF(D9="","",D9*'参数与说明'!$B$6/45.3592) | H9: =IFERROR(IF(D9="","",D9/INDEX($D:$D,MATCH(EDATE($A9,-1),$A:$A,0))-1),"") | I9: =IFERROR(IF(D9="","",D9/INDEX($D:$D,MATCH(EDATE($A9,-12),$A:$A,0))-1),"")
A10: 29373 | B10: 1980 | C10: 6 | D10: 12.5 | E10: 12.7 | F10: 11.7 | G10: =IF(D10="","",D10*'参数与说明'!$B$6/45.3592) | H10: =IFERROR(IF(D10="","",D10/INDEX($D:$D,MATCH(EDATE($A10,-1),$A:$A,0))-1),"") | I10: =IFERROR(IF(D10="","",D10/INDEX($D:$D,MATCH(EDATE($A10,-12),$A:$A,0))-1),"")
A11: 29403 | B11: 1980 | C11: 7 | D11: 12.6 | E11: 12.7 | F11: 11.6 | G11: =IF(D11="","",D11*'参数与说明'!$B$6/45.3592) | H11: =IFERROR(IF(D11="","",D11/INDEX($D:$D,MATCH(EDATE($A11,-1),$A:$A,0))-1),"") | I11: =IFERROR(IF(D11="","",D11/INDEX($D:$D,MATCH(EDATE($A11,-12),$A:$A,0))-1),"")
A12: 29434 | B12: 1980 | C12: 8 | D12: 12.8 | E12: 13 | F12: 11.8 | G12: =IF(D12="","",D12*'参数与说明'!$B$6/45.3592) | H12: =IFERROR(IF(D12="","",D12/INDEX($D:$D,MATCH(EDATE($A12,-1),$A:$A,0))-1),"") | I12: =IFERROR(IF(D12="","",D12/INDEX($D:$D,MATCH(EDATE($A12,-12),$A:$A,0))-1),"")
A13: 29465 | B13: 1980 | C13: 9 | D13: 13.2 | E13: 13.4 | F13: 12.2 | G13: =IF(D13="","",D13*'参数与说明'!$B$6/45.3592) | H13: =IFERROR(IF(D13="","",D13/INDEX($D:$D,MATCH(EDATE($A13,-1),$A:$A,0))-1),"") | I13: =IFERROR(IF(D13="","",D13/INDEX($D:$D,MATCH(EDATE($A13,-12),$A:$A,0))-1),"")
A14: 29495 | B14: 1980 | C14: 10 | D14: 13.7 | E14: 13.9 | F14: 12.7 | G14: =IF(D14="","",D14*'参数与说明'!$B$6/45.3592) | H14: =IFERROR(IF(D14="","",D14/INDEX($D:$D,MATCH(EDATE($A14,-1),$A:$A,0))-1),"") | I14: =IFERROR(IF(D14="","",D14/INDEX($D:$D,MATCH(EDATE($A14,-12),$A:$A,0))-1),"")
A15: 29526 | B15: 1980 | C15: 11 | D15: 14 | E15: 14.1 | F15: 12.9 | G15: =IF(D15="","",D15*'参数与说明'!$B$6/45.3592) | H15: =IFERROR(IF(D15="","",D15/INDEX($D:$D,MATCH(EDATE($A15,-1),$A:$A,0))-1),"") | I15: =IFERROR(IF(D15="","",D15/INDEX($D:$D,MATCH(EDATE($A15,-12),$A:$A,0))-1),"")
A16: 29556 | B16: 1980 | C16: 12 | D16: 14.1 | E16: 14.3 | F16: 13 | G16: =IF(D16="","",D16*'参数与说明'!$B$6/45.3592) | H16: =IFERROR(IF(D16="","",D16/INDEX($D:$D,MATCH(EDATE($A16,-1),$A:$A,0))-1),"") | I16: =IFERROR(IF(D16="","",D16/INDEX($D:$D,MATCH(EDATE($A16,-12),$A:$A,0))-1),"")
... A376: 40513 | B376: 2010 | C376: 12 | D376: 16.7 | E376: 16.8 | F376: 14.3 | G376: =IF(D376="","",D376*'参数与说明'!$B$6/45.3592) | H376: =IFERROR(IF(D376="","",D376/INDEX($D:$D,MATCH(EDATE($A376,-1),$A:$A,0))-1),"") | I376: =IFERROR(IF(D376="","",D376/INDEX($D:$D,MATCH(EDATE($A376,-12),$A:$A,0))-1),"")
A377: 40544 | B377: 2011 | C377: 1 | D377: 16.7 | G377: =IF(D377="","",D377*'参数与说明'!$B$6/45.3592) | H377: =IFERROR(IF(D377="","",D377/INDEX($D:$D,MATCH(EDATE($A377,-1),$A:$A,0))-1),"") | I377: =IFERROR(IF(D377="","",D377/INDEX($D:$D,MATCH(EDATE($A377,-12),$A:$A,0))-1),"")
A378: 40575 | B378: 2011 | C378: 2 | D378: 19.1 | G378: =IF(D378="","",D378*'参数与说明'!$B$6/45.3592) | H378: =IFERROR(IF(D378="","",D378/INDEX($D:$D,MATCH(EDATE($A378,-1),$A:$A,0))-1),"") | I378: =IFERROR(IF(D378="","",D378/INDEX($D:$D,MATCH(EDATE($A378,-12),$A:$A,0))-1),"")
A379: 40603 | B379: 2011 | C379: 3 | D379: 20.4 | G379: =IF(D379="","",D379*'参数与说明'!$B$6/45.3592) | H379: =IFERROR(IF(D379="","",D379/INDEX($D:$D,MATCH(EDATE($A379,-1),$A:$A,0))-1),"") | I379: =IFERROR(IF(D379="","",D379/INDEX($D:$D,MATCH(EDATE($A379,-12),$A:$A,0))-1),"")
A380: 40634 | B380: 2011 | C380: 4 | D380: 19.6 | G380: =IF(D380="","",D380*'参数与说明'!$B$6/45.3592) | H380: =IFERROR(IF(D380="","",D380/INDEX($D:$D,MATCH(EDATE($A380,-1),$A:$A,0))-1),"") | I380: =IFERROR(IF(D380="","",D380/INDEX($D:$D,MATCH(EDATE($A380,-12),$A:$A,0))-1),"")
A381: 40664 | B381: 2011 | C381: 5 | D381: 19.6 | G381: =IF(D381="","",D381*'参数与说明'!$B$6/45.3592) | H381: =IFERROR(IF(D381="","",D381/INDEX($D:$D,MATCH(EDATE($A381,-1),$A:$A,0))-1),"") | I381: =IFERROR(IF(D381="","",D381/INDEX($D:$D,MATCH(EDATE($A381,-12),$A:$A,0))-1),"")
A382: 40695 | B382: 2011 | C382: 6 | D382: 21.1 | G382: =IF(D382="","",D382*'参数与说明'!$B$6/45.3592) | H382: =IFERROR(IF(D382="","",D382/INDEX($D:$D,MATCH(EDATE($A382,-1),$A:$A,0))-1),"") | I382: =IFERROR(IF(D382="","",D382/INDEX($D:$D,MATCH(EDATE($A382,-12),$A:$A,0))-1),"")
A383: 40725 | B383: 2011 | C383: 7 | D383: 21.8 | G383: =IF(D383="","",D383*'参数与说明'!$B$6/45.3592) | H383: =IFERROR(IF(D383="","",D383/INDEX($D:$D,MATCH(EDATE($A383,-1),$A:$A,0))-1),"") | I383: =IFERROR(IF(D383="","",D383/INDEX($D:$D,MATCH(EDATE($A383,-12),$A:$A,0))-1),"")
A384: 40756 | B384: 2011 | C384: 8 | D384: 22.1 | G384: =IF(D384="","",D384*'参数与说明'!$B$6/45.3592) | H384: =IFERROR(IF(D384="","",D384/INDEX($D:$D,MATCH(EDATE($A384,-1),$A:$A,0))-1),"") | I384: =IFERROR(IF(D384="","",D384/INDEX($D:$D,MATCH(EDATE($A384,-12),$A:$A,0))-1),"")
A385: 40787 | B385: 2011 | C385: 9 | D385: 21.1 | G385: =IF(D385="","",D385*'参数与说明'!$B$6/45.3592) | H385: =IFERROR(IF(D385="","",D385/INDEX($D:$D,MATCH(EDATE($A385,-1),$A:$A,0))-1),"") | I385: =IFERROR(IF(D385="","",D385/INDEX($D:$D,MATCH(EDATE($A385,-12),$A:$A,0))-1),"")
A386: 40817 | B386: 2011 | C386: 10 | D386: 20 | G386: =IF(D386="","",D386*'参数与说明'!$B$6/45.3592) | H386: =IFERROR(IF(D386="","",D386/INDEX($D:$D,MATCH(EDATE($A386,-1),$A:$A,0))-1),"") | I386: =IFERROR(IF(D386="","",D386/INDEX($D:$D,MATCH(EDATE($A386,-12),$A:$A,0))-1),"")
A387: 40848 | B387: 2011 | C387: 11 | D387: 20.5 | G387: =IF(D387="","",D387*'参数与说明'!$B$6/45.3592) | H387: =IFERROR(IF(D387="","",D387/INDEX($D:$D,MATCH(EDATE($A387,-1),$A:$A,0))-1),"") | I387: =IFERROR(IF(D387="","",D387/INDEX($D:$D,MATCH(EDATE($A387,-12),$A:$A,0))-1),"")
A388: 40878 | B388: 2011 | C388: 12 | D388: 19.7 | G388: =IF(D388="","",D388*'参数与说明'!$B$6/45.3592) | H388: =IFERROR(IF(D388="","",D388/INDEX($D:$D,MATCH(EDATE($A388,-1),$A:$A,0))-1),"") | I388: =IFERROR(IF(D388="","",D388/INDEX($D:$D,MATCH(EDATE($A388,-12),$A:$A,0))-1),"")
... A564: 46235 | B564: 2026 | C564: 8 | D564: 19.8 | G564: =IF(D564="","",D564*'参数与说明'!$B$6/45.3592) | H564: =IFERROR(IF(D564="","",D564/INDEX($D:$D,MATCH(EDATE($A564,-1),$A:$A,0))-1),"") | I564: =IFERROR(IF(D564="","",D564/INDEX($D:$D,MATCH(EDATE($A564,-12),$A:$A,0))-1),"")

Sheet 鸡蛋
A1: 鸡蛋 — USDA NASS 价格收到价（月度）
A2: 美元/打(12枚)；元/公斤=主指标×汇率('参数与说明'!$B$6)÷0.68。趋势图用美制原值。
A4: 日期 | B4: 年 | C4: 月 | D4: 鸡蛋(全部) ($ / DOZEN) | E4: 商品蛋(Table eggs) ($ / DOZEN) | F4: 主指标(元/公斤) | G4: 环比% | H4: 同比%
A5: 36130 | B5: 1998 | C5: 12 | D5: 0.754 | F5: =IF(D5="","",D5*'参数与说明'!$B$6/0.68) | G5: =IFERROR(IF(D5="","",D5/INDEX($D:$D,MATCH(EDATE($A5,-1),$A:$A,0))-1),"") | H5: =IFERROR(IF(D5="","",D5/INDEX($D:$D,MATCH(EDATE($A5,-12),$A:$A,0))-1),"")
A6: 36161 | B6: 1999 | C6: 1 | D6: 0.724 | F6: =IF(D6="","",D6*'参数与说明'!$B$6/0.68) | G6: =IFERROR(IF(D6="","",D6/INDEX($D:$D,MATCH(EDATE($A6,-1),$A:$A,0))-1),"") | H6: =IFERROR(IF(D6="","",D6/INDEX($D:$D,MATCH(EDATE($A6,-12),$A:$A,0))-1),"")
A7: 36192 | B7: 1999 | C7: 2 | D7: 0.66 | F7: =IF(D7="","",D7*'参数与说明'!$B$6/0.68) | G7: =IFERROR(IF(D7="","",D7/INDEX($D:$D,MATCH(EDATE($A7,-1),$A:$A,0))-1),"") | H7: =IFERROR(IF(D7="","",D7/INDEX($D:$D,MATCH(EDATE($A7,-12),$A:$A,0))-1),"")
A8: 36220 | B8: 1999 | C8: 3 | D8: 0.685 | F8: =IF(D8="","",D8*'参数与说明'!$B$6/0.68) | G8: =IFERROR(IF(D8="","",D8/INDEX($D:$D,MATCH(EDATE($A8,-1),$A:$A,0))-1),"") | H8: =IFERROR(IF(D8="","",D8/INDEX($D:$D,MATCH(EDATE($A8,-12),$A:$A,0))-1),"")
A9: 36251 | B9: 1999 | C9: 4 | D9: 0.602 | F9: =IF(D9="","",D9*'参数与说明'!$B$6/0.68) | G9: =IFERROR(IF(D9="","",D9/INDEX($D:$D,MATCH(EDATE($A9,-1),$A:$A,0))-1),"") | H9: =IFERROR(IF(D9="","",D9/INDEX($D:$D,MATCH(EDATE($A9,-12),$A:$A,0))-1),"")
A10: 36281 | B10: 1999 | C10: 5 | D10: 0.548 | F10: =IF(D10="","",D10*'参数与说明'!$B$6/0.68) | G10: =IFERROR(IF(D10="","",D10/INDEX($D:$D,MATCH(EDATE($A10,-1),$A:$A,0))-1),"") | H10: =IFERROR(IF(D10="","",D10/INDEX($D:$D,MATCH(EDATE($A10,-12),$A:$A,0))-1),"")
A11: 36312 | B11: 1999 | C11: 6 | D11: 0.562 | F11: =IF(D11="","",D11*'参数与说明'!$B$6/0.68) | G11: =IFERROR(IF(D11="","",D11/INDEX($D:$D,MATCH(EDATE($A11,-1),$A:$A,0))-1),"") | H11: =IFERROR(IF(D11="","",D11/INDEX($D:$D,MATCH(EDATE($A11,-12),$A:$A,0))-1),"")
A12: 36342 | B12: 1999 | C12: 7 | D12: 0.587 | F12: =IF(D12="","",D12*'参数与说明'!$B$6/0.68) | G12: =IFERROR(IF(D12="","",D12/INDEX($D:$D,MATCH(EDATE($A12,-1),$A:$A,0))-1),"") | H12: =IFERROR(IF(D12="","",D12/INDEX($D:$D,MATCH(EDATE($A12,-12),$A:$A,0))-1),"")
A13: 36373 | B13: 1999 | C13: 8 | D13: 0.596 | F13: =IF(D13="","",D13*'参数与说明'!$B$6/0.68) | G13: =IFERROR(IF(D13="","",D13/INDEX($D:$D,MATCH(EDATE($A13,-1),$A:$A,0))-1),"") | H13: =IFERROR(IF(D13="","",D13/INDEX($D:$D,MATCH(EDATE($A13,-12),$A:$A,0))-1),"")
A14: 36404 | B14: 1999 | C14: 9 | D14: 0.574 | F14: =IF(D14="","",D14*'参数与说明'!$B$6/0.68) | G14: =IFERROR(IF(D14="","",D14/INDEX($D:$D,MATCH(EDATE($A14,-1),$A:$A,0))-1),"") | H14: =IFERROR(IF(D14="","",D14/INDEX($D:$D,MATCH(EDATE($A14,-12),$A:$A,0))-1),"")
A15: 36434 | B15: 1999 | C15: 10 | D15: 0.519 | F15: =IF(D15="","",D15*'参数与说明'!$B$6/0.68) | G15: =IFERROR(IF(D15="","",D15/INDEX($D:$D,MATCH(EDATE($A15,-1),$A:$A,0))-1),"") | H15: =IFERROR(IF(D15="","",D15/INDEX($D:$D,MATCH(EDATE($A15,-12),$A:$A,0))-1),"")
A16: 36465 | B16: 1999 | C16: 11 | D16: 0.64 | F16: =IF(D16="","",D16*'参数与说明'!$B$6/0.68) | G16: =IFERROR(IF(D16="","",D16/INDEX($D:$D,MATCH(EDATE($A16,-1),$A:$A,0))-1),"") | H16: =IFERROR(IF(D16="","",D16/INDEX($D:$D,MATCH(EDATE($A16,-12),$A:$A,0))-1),"")
... A28: 36831 | B28: 2000 | C28: 11 | D28: 0.719 | F28: =IF(D28="","",D28*'参数与说明'!$B$6/0.68) | G28: =IFERROR(IF(D28="","",D28/INDEX($D:$D,MATCH(EDATE($A28,-1),$A:$A,0))-1),"") | H28: =IFERROR(IF(D28="","",D28/INDEX($D:$D,MATCH(EDATE($A28,-12),$A:$A,0))-1),"")
A29: 36861 | B29: 2000 | C29: 12 | D29: 0.806 | E29: 0.674 | F29: =IF(D29="","",D29*'参数与说明'!$B$6/0.68) | G29: =IFERROR(IF(D29="","",D29/INDEX($D:$D,MATCH(EDATE($A29,-1),$A:$A,0))-1),"") | H29: =IFERROR(IF(D29="","",D29/INDEX($D:$D,MATCH(EDATE($A29,-12),$A:$A,0))-1),"")
A30: 36892 | B30: 2001 | C30: 1 | D30: 0.668 | E30: 0.507 | F30: =IF(D30="","",D30*'参数与说明'!$B$6/0.68) | G30: =IFERROR(IF(D30="","",D30/INDEX($D:$D,MATCH(EDATE($A30,-1),$A:$A,0))-1),"") | H30: =IFERROR(IF(D30="","",D30/INDEX($D:$D,MATCH(EDATE($A30,-12),$A:$A,0))-1),"")
A31: 36923 | B31: 2001 | C31: 2 | D31: 0.665 | E31: 0.501 | F31: =IF(D31="","",D31*'参数与说明'!$B$6/0.68) | G31: =IFERROR(IF(D31="","",D31/INDEX($D:$D,MATCH(EDATE($A31,-1),$A:$A,0))-1),"") | H31: =IFERROR(IF(D31="","",D31/INDEX($D:$D,MATCH(EDATE($A31,-12),$A:$A,0))-1),"")
A32: 36951 | B32: 2001 | C32: 3 | D32: 0.676 | E32: 0.517 | F32: =IF(D32="","",D32*'参数与说明'!$B$6/0.68) | G32: =IFERROR(IF(D32="","",D32/INDEX($D:$D,MATCH(EDATE($A32,-1),$A:$A,0))-1),"") | H32: =IFERROR(IF(D32="","",D32/INDEX($D:$D,MATCH(EDATE($A32,-12),$A:$A,0))-1),"")
A33: 36982 | B33: 2001 | C33: 4 | D33: 0.649 | E33: 0.484 | F33: =IF(D33="","",D33*'参数与说明'!$B$6/0.68) | G33: =IFERROR(IF(D33="","",D33/INDEX($D:$D,MATCH(EDATE($A33,-1),$A:$A,0))-1),"") | H33: =IFERROR(IF(D33="","",D33/INDEX($D:$D,MATCH(EDATE($A33,-12),$A:$A,0))-1),"")
A34: 37012 | B34: 2001 | C34: 5 | D34: 0.552 | E34: 0.365 | F34: =IF(D34="","",D34*'参数与说明'!$B$6/0.68) | G34: =IFERROR(IF(D34="","",D34/INDEX($D:$D,MATCH(EDATE($A34,-1),$A:$A,0))-1),"") | H34: =IFERROR(IF(D34="","",D34/INDEX($D:$D,MATCH(EDATE($A34,-12),$A:$A,0))-1),"")
A35: 37043 | B35: 2001 | C35: 6 | D35: 0.549 | E35: 0.362 | F35: =IF(D35="","",D35*'参数与说明'!$B$6/0.68) | G35: =IFERROR(IF(D35="","",D35/INDEX($D:$D,MATCH(EDATE($A35,-1),$A:$A,0))-1),"") | H35: =IFERROR(IF(D35="","",D35/INDEX($D:$D,MATCH(EDATE($A35,-12),$A:$A,0))-1),"")
A36: 37073 | B36: 2001 | C36: 7 | D36: 0.539 | E36: 0.353 | F36: =IF(D36="","",D36*'参数与说明'!$B$6/0.68) | G36: =IFERROR(IF(D36="","",D36/INDEX($D:$D,MATCH(EDATE($A36,-1),$A:$A,0))-1),"") | H36: =IFERROR(IF(D36="","",D36/INDEX($D:$D,MATCH(EDATE($A36,-12),$A:$A,0))-1),"")
A37: 37104 | B37: 2001 | C37: 8 | D37: 0.565 | E37: 0.388 | F37: =IF(D37="","",D37*'参数与说明'!$B$6/0.68) | G37: =IFERROR(IF(D37="","",D37/INDEX($D:$D,MATCH(EDATE($A37,-1),$A:$A,0))-1),"") | H37: =IFERROR(IF(D37="","",D37/INDEX($D:$D,MATCH(EDATE($A37,-12),$A:$A,0))-1),"")
A38: 37135 | B38: 2001 | C38: 9 | D38: 0.554 | E38: 0.377 | F38: =IF(D38="","",D38*'参数与说明'!$B$6/0.68) | G38: =IFERROR(IF(D38="","",D38/INDEX($D:$D,MATCH(EDATE($A38,-1),$A:$A,0))-1),"") | H38: =IFERROR(IF(D38="","",D38/INDEX($D:$D,MATCH(EDATE($A38,-12),$A:$A,0))-1),"")
A39: 37165 | B39: 2001 | C39: 10 | D39: 0.597 | E39: 0.43 | F39: =IF(D39="","",D39*'参数与说明'!$B$6/0.68) | G39: =IFERROR(IF(D39="","",D39/INDEX($D:$D,MATCH(EDATE($A39,-1),$A:$A,0))-1),"") | H39: =IFERROR(IF(D39="","",D39/INDEX($D:$D,MATCH(EDATE($A39,-12),$A:$A,0))-1),"")
A40: 37196 | B40: 2001 | C40: 11 | D40: 0.641 | E40: 0.486 | F40: =IF(D40="","",D40*'参数与说明'!$B$6/0.68) | G40: =IFERROR(IF(D40="","",D40/INDEX($D:$D,MATCH(EDATE($A40,-1),$A:$A,0))-1),"") | H40: =IFERROR(IF(D40="","",D40/INDEX($D:$D,MATCH(EDATE($A40,-12),$A:$A,0))-1),"")
... A337: 46235 | B337: 2026 | C337: 8 | D337: 1.03 | E337: 0.77 | F337: =IF(D337="","",D337*'参数与说明'!$B$6/0.68) | G337: =IFERROR(IF(D337="","",D337/INDEX($D:$D,MATCH(EDATE($A337,-1),$A:$A,0))-1),"") | H337: =IFERROR(IF(D337="","",D337/INDEX($D:$D,MATCH(EDATE($A337,-12),$A:$A,0))-1),"")

Sheet 鸡肉
A1: 鸡肉 — USDA NASS 价格收到价（月度）
A2: 美元/磅(lb)；元/公斤=主指标×汇率('参数与说明'!$B$6)÷0.453592。趋势图用美制原值。
A4: 日期 | B4: 年 | C4: 月 | D4: 肉鸡(Broilers) ($ / LB) | E4: 主指标(元/公斤) | F4: 环比% | G4: 同比%
A5: 33239 | B5: 1991 | C5: 1 | D5: 0.305 | E5: =IF(D5="","",D5*'参数与说明'!$B$6/0.453592) | F5: =IFERROR(IF(D5="","",D5/INDEX($D:$D,MATCH(EDATE($A5,-1),$A:$A,0))-1),"") | G5: =IFERROR(IF(D5="","",D5/INDEX($D:$D,MATCH(EDATE($A5,-12),$A:$A,0))-1),"")
A6: 33270 | B6: 1991 | C6: 2 | D6: 0.302 | E6: =IF(D6="","",D6*'参数与说明'!$B$6/0.453592) | F6: =IFERROR(IF(D6="","",D6/INDEX($D:$D,MATCH(EDATE($A6,-1),$A:$A,0))-1),"") | G6: =IFERROR(IF(D6="","",D6/INDEX($D:$D,MATCH(EDATE($A6,-12),$A:$A,0))-1),"")
A7: 33298 | B7: 1991 | C7: 3 | D7: 0.301 | E7: =IF(D7="","",D7*'参数与说明'!$B$6/0.453592) | F7: =IFERROR(IF(D7="","",D7/INDEX($D:$D,MATCH(EDATE($A7,-1),$A:$A,0))-1),"") | G7: =IFERROR(IF(D7="","",D7/INDEX($D:$D,MATCH(EDATE($A7,-12),$A:$A,0))-1),"")
A8: 33329 | B8: 1991 | C8: 4 | D8: 0.307 | E8: =IF(D8="","",D8*'参数与说明'!$B$6/0.453592) | F8: =IFERROR(IF(D8="","",D8/INDEX($D:$D,MATCH(EDATE($A8,-1),$A:$A,0))-1),"") | G8: =IFERROR(IF(D8="","",D8/INDEX($D:$D,MATCH(EDATE($A8,-12),$A:$A,0))-1),"")
A9: 33359 | B9: 1991 | C9: 5 | D9: 0.311 | E9: =IF(D9="","",D9*'参数与说明'!$B$6/0.453592) | F9: =IFERROR(IF(D9="","",D9/INDEX($D:$D,MATCH(EDATE($A9,-1),$A:$A,0))-1),"") | G9: =IFERROR(IF(D9="","",D9/INDEX($D:$D,MATCH(EDATE($A9,-12),$A:$A,0))-1),"")
A10: 33390 | B10: 1991 | C10: 6 | D10: 0.315 | E10: =IF(D10="","",D10*'参数与说明'!$B$6/0.453592) | F10: =IFERROR(IF(D10="","",D10/INDEX($D:$D,MATCH(EDATE($A10,-1),$A:$A,0))-1),"") | G10: =IFERROR(IF(D10="","",D10/INDEX($D:$D,MATCH(EDATE($A10,-12),$A:$A,0))-1),"")
A11: 33420 | B11: 1991 | C11: 7 | D11: 0.323 | E11: =IF(D11="","",D11*'参数与说明'!$B$6/0.453592) | F11: =IFERROR(IF(D11="","",D11/INDEX($D:$D,MATCH(EDATE($A11,-1),$A:$A,0))-1),"") | G11: =IFERROR(IF(D11="","",D11/INDEX($D:$D,MATCH(EDATE($A11,-12),$A:$A,0))-1),"")
A12: 33451 | B12: 1991 | C12: 8 | D12: 0.324 | E12: =IF(D12="","",D12*'参数与说明'!$B$6/0.453592) | F12: =IFERROR(IF(D12="","",D12/INDEX($D:$D,MATCH(EDATE($A12,-1),$A:$A,0))-1),"") | G12: =IFERROR(IF(D12="","",D12/INDEX($D:$D,MATCH(EDATE($A12,-12),$A:$A,0))-1),"")
A13: 33482 | B13: 1991 | C13: 9 | D13: 0.321 | E13: =IF(D13="","",D13*'参数与说明'!$B$6/0.453592) | F13: =IFERROR(IF(D13="","",D13/INDEX($D:$D,MATCH(EDATE($A13,-1),$A:$A,0))-1),"") | G13: =IFERROR(IF(D13="","",D13/INDEX($D:$D,MATCH(EDATE($A13,-12),$A:$A,0))-1),"")
A14: 33512 | B14: 1991 | C14: 10 | D14: 0.31 | E14: =IF(D14="","",D14*'参数与说明'!$B$6/0.453592) | F14: =IFERROR(IF(D14="","",D14/INDEX($D:$D,MATCH(EDATE($A14,-1),$A:$A,0))-1),"") | G14: =IFERROR(IF(D14="","",D14/INDEX($D:$D,MATCH(EDATE($A14,-12),$A:$A,0))-1),"")
A15: 33543 | B15: 1991 | C15: 11 | D15: 0.295 | E15: =IF(D15="","",D15*'参数与说明'!$B$6/0.453592) | F15: =IFERROR(IF(D15="","",D15/INDEX($D:$D,MATCH(EDATE($A15,-1),$A:$A,0))-1),"") | G15: =IFERROR(IF(D15="","",D15/INDEX($D:$D,MATCH(EDATE($A15,-12),$A:$A,0))-1),"")
A16: 33573 | B16: 1991 | C16: 12 | D16: 0.295 | E16: =IF(D16="","",D16*'参数与说明'!$B$6/0.453592) | F16: =IFERROR(IF(D16="","",D16/INDEX($D:$D,MATCH(EDATE($A16,-1),$A:$A,0))-1),"") | G16: =IFERROR(IF(D16="","",D16/INDEX($D:$D,MATCH(EDATE($A16,-12),$A:$A,0))-1),"")
... A432: 46235 | B432: 2026 | C432: 8 | D432: 0.653 | E432: =IF(D432="","",D432*'参数与说明'!$B$6/0.453592) | F432: =IFERROR(IF(D432="","",D432/INDEX($D:$D,MATCH(EDATE($A432,-1),$A:$A,0))-1),"") | G432: =IFERROR(IF(D432="","",D432/INDEX($D:$D,MATCH(EDATE($A432,-12),$A:$A,0))-1),"")

Sheet 玉米
A1: 玉米 — USDA NASS 价格收到价（月度）
A2: 美元/蒲式耳(玉米1bu=25.40kg)；元/公斤=主指标×汇率('参数与说明'!$B$6)÷25.4012。趋势图用美制原值。
A4: 日期 | B4: 年 | C4: 月 | D4: 玉米(Corn grain) ($ / BU) | E4: 主指标(元/公斤) | F4: 环比% | G4: 同比%
A5: 2923 | B5: 1908 | C5: 1 | D5: 0.55 | E5: =IF(D5="","",D5*'参数与说明'!$B$6/25.4012) | F5: =IFERROR(IF(D5="","",D5/INDEX($D:$D,MATCH(EDATE($A5,-1),$A:$A,0))-1),"") | G5: =IFERROR(IF(D5="","",D5/INDEX($D:$D,MATCH(EDATE($A5,-12),$A:$A,0))-1),"")
A6: 2954 | B6: 1908 | C6: 2 | D6: 0.57 | E6: =IF(D6="","",D6*'参数与说明'!$B$6/25.4012) | F6: =IFERROR(IF(D6="","",D6/INDEX($D:$D,MATCH(EDATE($A6,-1),$A:$A,0))-1),"") | G6: =IFERROR(IF(D6="","",D6/INDEX($D:$D,MATCH(EDATE($A6,-12),$A:$A,0))-1),"")
A7: 2983 | B7: 1908 | C7: 3 | D7: 0.596 | E7: =IF(D7="","",D7*'参数与说明'!$B$6/25.4012) | F7: =IFERROR(IF(D7="","",D7/INDEX($D:$D,MATCH(EDATE($A7,-1),$A:$A,0))-1),"") | G7: =IFERROR(IF(D7="","",D7/INDEX($D:$D,MATCH(EDATE($A7,-12),$A:$A,0))-1),"")
A8: 3014 | B8: 1908 | C8: 4 | D8: 0.63 | E8: =IF(D8="","",D8*'参数与说明'!$B$6/25.4012) | F8: =IFERROR(IF(D8="","",D8/INDEX($D:$D,MATCH(EDATE($A8,-1),$A:$A,0))-1),"") | G8: =IFERROR(IF(D8="","",D8/INDEX($D:$D,MATCH(EDATE($A8,-12),$A:$A,0))-1),"")
A9: 3044 | B9: 1908 | C9: 5 | D9: 0.692 | E9: =IF(D9="","",D9*'参数与说明'!$B$6/25.4012) | F9: =IFERROR(IF(D9="","",D9/INDEX($D:$D,MATCH(EDATE($A9,-1),$A:$A,0))-1),"") | G9: =IFERROR(IF(D9="","",D9/INDEX($D:$D,MATCH(EDATE($A9,-12),$A:$A,0))-1),"")
A10: 3075 | B10: 1908 | C10: 6 | D10: 0.747 | E10: =IF(D10="","",D10*'参数与说明'!$B$6/25.4012) | F10: =IFERROR(IF(D10="","",D10/INDEX($D:$D,MATCH(EDATE($A10,-1),$A:$A,0))-1),"") | G10: =IFERROR(IF(D10="","",D10/INDEX($D:$D,MATCH(EDATE($A10,-12),$A:$A,0))-1),"")
A11: 3105 | B11: 1908 | C11: 7 | D11: 0.769 | E11: =IF(D11="","",D11*'参数与说明'!$B$6/25.4012) | F11: =IFERROR(IF(D11="","",D11/INDEX($D:$D,MATCH(EDATE($A11,-1),$A:$A,0))-1),"") | G11: =IFERROR(IF(D11="","",D11/INDEX($D:$D,MATCH(EDATE($A11,-12),$A:$A,0))-1),"")
A12: 3136 | B12: 1908 | C12: 8 | D12: 0.773 | E12: =IF(D12="","",D12*'参数与说明'!$B$6/25.4012) | F12: =IFERROR(IF(D12="","",D12/INDEX($D:$D,MATCH(EDATE($A12,-1),$A:$A,0))-1),"") | G12: =IFERROR(IF(D12="","",D12/INDEX($D:$D,MATCH(EDATE($A12,-12),$A:$A,0))-1),"")
A13: 3167 | B13: 1908 | C13: 9 | D13: 0.744 | E13: =IF(D13="","",D13*'参数与说明'!$B$6/25.4012) | F13: =IFERROR(IF(D13="","",D13/INDEX($D:$D,MATCH(EDATE($A13,-1),$A:$A,0))-1),"") | G13: =IFERROR(IF(D13="","",D13/INDEX($D:$D,MATCH(EDATE($A13,-12),$A:$A,0))-1),"")
A14: 3197 | B14: 1908 | C14: 10 | D14: 0.679 | E14: =IF(D14="","",D14*'参数与说明'!$B$6/25.4012) | F14: =IFERROR(IF(D14="","",D14/INDEX($D:$D,MATCH(EDATE($A14,-1),$A:$A,0))-1),"") | G14: =IFERROR(IF(D14="","",D14/INDEX($D:$D,MATCH(EDATE($A14,-12),$A:$A,0))-1),"")
A15: 3228 | B15: 1908 | C15: 11 | D15: 0.62 | E15: =IF(D15="","",D15*'参数与说明'!$B$6/25.4012) | F15: =IFERROR(IF(D15="","",D15/INDEX($D:$D,MATCH(EDATE($A15,-1),$A:$A,0))-1),"") | G15: =IFERROR(IF(D15="","",D15/INDEX($D:$D,MATCH(EDATE($A15,-12),$A:$A,0))-1),"")
A16: 3258 | B16: 1908 | C16: 12 | D16: 0.606 | E16: =IF(D16="","",D16*'参数与说明'!$B$6/25.4012) | F16: =IFERROR(IF(D16="","",D16/INDEX($D:$D,MATCH(EDATE($A16,-1),$A:$A,0))-1),"") | G16: =IFERROR(IF(D16="","",D16/INDEX($D:$D,MATCH(EDATE($A16,-12),$A:$A,0))-1),"")
... A1428: 46235 | B1428: 2026 | C1428: 8 | D1428: 4.45 | E1428: =IF(D1428="","",D1428*'参数与说明'!$B$6/25.4012) | F1428: =IFERROR(IF(D1428="","",D1428/INDEX($D:$D,MATCH(EDATE($A1428,-1),$A:$A,0))-1),"") | G1428: =IFERROR(IF(D1428="","",D1428/INDEX($D:$D,MATCH(EDATE($A1428,-12),$A:$A,0))-1),"")

Sheet 大豆
A1: 大豆 — USDA NASS 价格收到价（月度）
A2: 美元/蒲式耳(大豆1bu=27.22kg)；元/公斤=主指标×汇率('参数与说明'!$B$6)÷27.2155。趋势图用美制原值。
A4: 日期 | B4: 年 | C4: 月 | D4: 大豆(Soybeans) ($ / BU) | E4: 主指标(元/公斤) | F4: 环比% | G4: 同比%
A5: 5023 | B5: 1913 | C5: 10 | D5: 1.96 | E5: =IF(D5="","",D5*'参数与说明'!$B$6/27.2155) | F5: =IFERROR(IF(D5="","",D5/INDEX($D:$D,MATCH(EDATE($A5,-1),$A:$A,0))-1),"") | G5: =IFERROR(IF(D5="","",D5/INDEX($D:$D,MATCH(EDATE($A5,-12),$A:$A,0))-1),"")
A6: 5054 | B6: 1913 | C6: 11 | D6: 1.57 | E6: =IF(D6="","",D6*'参数与说明'!$B$6/27.2155) | F6: =IFERROR(IF(D6="","",D6/INDEX($D:$D,MATCH(EDATE($A6,-1),$A:$A,0))-1),"") | G6: =IFERROR(IF(D6="","",D6/INDEX($D:$D,MATCH(EDATE($A6,-12),$A:$A,0))-1),"")
A7: 5084 | B7: 1913 | C7: 12 | D7: 1.72 | E7: =IF(D7="","",D7*'参数与说明'!$B$6/27.2155) | F7: =IFERROR(IF(D7="","",D7/INDEX($D:$D,MATCH(EDATE($A7,-1),$A:$A,0))-1),"") | G7: =IFERROR(IF(D7="","",D7/INDEX($D:$D,MATCH(EDATE($A7,-12),$A:$A,0))-1),"")
A8: 5115 | B8: 1914 | C8: 1 | D8: 1.96 | E8: =IF(D8="","",D8*'参数与说明'!$B$6/27.2155) | F8: =IFERROR(IF(D8="","",D8/INDEX($D:$D,MATCH(EDATE($A8,-1),$A:$A,0))-1),"") | G8: =IFERROR(IF(D8="","",D8/INDEX($D:$D,MATCH(EDATE($A8,-12),$A:$A,0))-1),"")
A9: 5146 | B9: 1914 | C9: 2 | D9: 1.8 | E9: =IF(D9="","",D9*'参数与说明'!$B$6/27.2155) | F9: =IFERROR(IF(D9="","",D9/INDEX($D:$D,MATCH(EDATE($A9,-1),$A:$A,0))-1),"") | G9: =IFERROR(IF(D9="","",D9/INDEX($D:$D,MATCH(EDATE($A9,-12),$A:$A,0))-1),"")
A10: 5388 | B10: 1914 | C10: 10 | D10: 2.08 | E10: =IF(D10="","",D10*'参数与说明'!$B$6/27.2155) | F10: =IFERROR(IF(D10="","",D10/INDEX($D:$D,MATCH(EDATE($A10,-1),$A:$A,0))-1),"") | G10: =IFERROR(IF(D10="","",D10/INDEX($D:$D,MATCH(EDATE($A10,-12),$A:$A,0))-1),"")
A11: 5419 | B11: 1914 | C11: 11 | D11: 2.15 | E11: =IF(D11="","",D11*'参数与说明'!$B$6/27.2155) | F11: =IFERROR(IF(D11="","",D11/INDEX($D:$D,MATCH(EDATE($A11,-1),$A:$A,0))-1),"") | G11: =IFERROR(IF(D11="","",D11/INDEX($D:$D,MATCH(EDATE($A11,-12),$A:$A,0))-1),"")
A12: 5449 | B12: 1914 | C12: 12 | D12: 2.24 | E12: =IF(D12="","",D12*'参数与说明'!$B$6/27.2155) | F12: =IFERROR(IF(D12="","",D12/INDEX($D:$D,MATCH(EDATE($A12,-1),$A:$A,0))-1),"") | G12: =IFERROR(IF(D12="","",D12/INDEX($D:$D,MATCH(EDATE($A12,-12),$A:$A,0))-1),"")
A13: 5480 | B13: 1915 | C13: 1 | D13: 2.35 | E13: =IF(D13="","",D13*'参数与说明'!$B$6/27.2155) | F13: =IFERROR(IF(D13="","",D13/INDEX($D:$D,MATCH(EDATE($A13,-1),$A:$A,0))-1),"") | G13: =IFERROR(IF(D13="","",D13/INDEX($D:$D,MATCH(EDATE($A13,-12),$A:$A,0))-1),"")
A14: 5511 | B14: 1915 | C14: 2 | D14: 2.26 | E14: =IF(D14="","",D14*'参数与说明'!$B$6/27.2155) | F14: =IFERROR(IF(D14="","",D14/INDEX($D:$D,MATCH(EDATE($A14,-1),$A:$A,0))-1),"") | G14: =IFERROR(IF(D14="","",D14/INDEX($D:$D,MATCH(EDATE($A14,-12),$A:$A,0))-1),"")
A15: 5753 | B15: 1915 | C15: 10 | D15: 1.88 | E15: =IF(D15="","",D15*'参数与说明'!$B$6/27.2155) | F15: =IFERROR(IF(D15="","",D15/INDEX($D:$D,MATCH(EDATE($A15,-1),$A:$A,0))-1),"") | G15: =IFERROR(IF(D15="","",D15/INDEX($D:$D,MATCH(EDATE($A15,-12),$A:$A,0))-1),"")
A16: 5784 | B16: 1915 | C16: 11 | D16: 2.08 | E16: =IF(D16="","",D16*'参数与说明'!$B$6/27.2155) | F16: =IFERROR(IF(D16="","",D16/INDEX($D:$D,MATCH(EDATE($A16,-1),$A:$A,0))-1),"") | G16: =IFERROR(IF(D16="","",D16/INDEX($D:$D,MATCH(EDATE($A16,-12),$A:$A,0))-1),"")
... A1290: 46235 | B1290: 2026 | C1290: 8 | D1290: 12.1 | E1290: =IF(D1290="","",D1290*'参数与说明'!$B$6/27.2155) | F1290: =IFERROR(IF(D1290="","",D1290/INDEX($D:$D,MATCH(EDATE($A1290,-1),$A:$A,0))-1),"") | G1290: =IFERROR(IF(D1290="","",D1290/INDEX($D:$D,MATCH(EDATE($A1290,-12),$A:$A,0))-1),"")
