Workbook

Sheet 生猪产品价格
A1: 时间 | B1: 周期 | C1: 仔猪价格（元/kg） | D1: 生猪价格（元/kg） | E1: 生猪(出栏)价格（元/kg） | F1: 猪肉价格（元/kg） | G1: 仔猪环比 | H1: 仔猪同比 | I1: 生猪环比 | J1: 生猪同比 | K1: 生猪(出栏)环比 | L1: 生猪(出栏)同比 | M1: 猪肉环比 | N1: 猪肉同比
A2: 46183 | B2: 6月第1周 | C2: =集贸价格明细!H2 -> 23.3 | D2: =集贸价格明细!H3 -> 10.14 | F2: =集贸价格明细!H4 -> 19.84 | G2: =集贸价格明细!K2 -> -0.6 | H2: =集贸价格明细!M2 -> -39 | I2: =集贸价格明细!K3 -> 0 | J2: =集贸价格明细!M3 -> -31.4 | M2: =集贸价格明细!K4 -> -0.5 | N2: =集贸价格明细!M4 -> -22.2
A3: 46176 | B3: 5月第4周 | C3: =集贸价格明细!H24 -> 23.44 | D3: =集贸价格明细!H25 -> 10.14 | F3: =集贸价格明细!H26 -> 19.94 | G3: =集贸价格明细!K24 -> 0.2 | H3: =集贸价格明细!M24 -> -39.3 | I3: =集贸价格明细!K25 -> 0.2 | J3: =集贸价格明细!M25 -> -31.7 | M3: =集贸价格明细!K26 -> -0.2 | N3: =集贸价格明细!M26 -> -22.1
A4: 46168 | B4: 5月第3周 | C4: =集贸价格明细!H46 -> 23.39 | D4: =集贸价格明细!H47 -> 10.12 | F4: =集贸价格明细!H48 -> 19.98 | G4: =集贸价格明细!K46 -> 0.3 | H4: =集贸价格明细!M46 -> -40 | I4: =集贸价格明细!K47 -> -0.4 | J4: =集贸价格明细!M47 -> -32.2 | M4: =集贸价格明细!K48 -> -0.4 | N4: =集贸价格明细!M48 -> -22.2
A5: 46162 | B5: 5月第2周 | C5: =集贸价格明细!H68 -> 23.31 | D5: =集贸价格明细!H69 -> 10.16 | F5: =集贸价格明细!H70 -> 20.06 | G5: =集贸价格明细!K68 -> 0.2 | H5: =集贸价格明细!M68 -> -40.8 | I5: =集贸价格明细!K69 -> -0.3 | J5: =集贸价格明细!M69 -> -32.7 | M5: =集贸价格明细!K70 -> -0.3 | N5: =集贸价格明细!M70 -> -22.4
A6: 46156 | B6: 5月第1周 | C6: =集贸价格明细!H90 -> 23.26 | D6: =集贸价格明细!H91 -> 10.19 | F6: =集贸价格明细!H92 -> 20.12 | G6: =集贸价格明细!K90 -> 0.6 | H6: =集贸价格明细!M90 -> -41.2 | I6: =集贸价格明细!K91 -> 0.1 | J6: =集贸价格明细!M91 -> -32.8 | M6: =集贸价格明细!K92 -> 0 | N6: =集贸价格明细!M92 -> -22.6
A7: 46151 | B7: 4月第5周 | C7: =集贸价格明细!H112 -> 23.11 | D7: =集贸价格明细!H113 -> 10.18 | F7: =集贸价格明细!H114 -> 20.12 | G7: =集贸价格明细!K112 -> 0.7 | H7: =集贸价格明细!M112 -> -41.5 | I7: =集贸价格明细!K113 -> 1.8 | J7: =集贸价格明细!M113 -> -33.1 | M7: =集贸价格明细!K114 -> 0.2 | N7: =集贸价格明细!M114 -> -22.7
A8: 46151 | B8: 4月第4周 | C8: =集贸价格明细!H134 -> 22.94 | D8: =集贸价格明细!H135 -> 10 | F8: =集贸价格明细!H136 -> 20.08 | G8: =集贸价格明细!K134 -> -0.7 | H8: =集贸价格明细!M134 -> -41.9 | I8: =集贸价格明细!K135 -> 2.6 | J8: =集贸价格明细!M135 -> -34.6 | M8: =集贸价格明细!K136 -> -0.1 | N8: =集贸价格明细!M136 -> -23.1
A9: 46134 | B9: 4月第3周 | C9: =集贸价格明细!H156 -> 23.11 | D9: =集贸价格明细!H157 -> 9.75 | F9: =集贸价格明细!H158 -> 20.1 | G9: =集贸价格明细!K156 -> -2.8 | H9: =集贸价格明细!M156 -> -41 | I9: =集贸价格明细!K157 -> -2.8 | J9: =集贸价格明细!M157 -> -35.9 | M9: =集贸价格明细!K158 -> -2 | N9: =集贸价格明细!M158 -> -22.9
A10: 46127 | B10: 4月第2周 | C10: =集贸价格明细!H178 -> 23.77 | D10: =集贸价格明细!H179 -> 10.03 | F10: =集贸价格明细!H180 -> 20.5 | G10: =集贸价格明细!K178 -> -3.2 | H10: =集贸价格明细!M178 -> -39 | I10: =集贸价格明细!K179 -> -3.6 | J10: =集贸价格明细!M179 -> -33.7 | M10: =集贸价格明细!K180 -> -2.5 | N10: =集贸价格明细!M180 -> -21.2
A11: 46120 | B11: 4月第1周 | C11: =集贸价格明细!H200 -> 24.56 | D11: =集贸价格明细!H201 -> 10.4 | F11: =集贸价格明细!H202 -> 21.03 | G11: =集贸价格明细!K200 -> -3.4 | H11: =集贸价格明细!M200 -> -36.5 | I11: =集贸价格明细!K201 -> -2.6 | J11: =集贸价格明细!M201 -> -31.4 | M11: =集贸价格明细!K202 -> -2.3 | N11: =集贸价格明细!M202 -> -19.5
A12: 46111 | B12: 3月第4周 | C12: =集贸价格明细!H222 -> 25.42 | D12: =集贸价格明细!H223 -> 10.68 | F12: =集贸价格明细!H224 -> 21.52 | G12: =集贸价格明细!K222 -> -3 | H12: =集贸价格明细!M222 -> -33.3 | I12: =集贸价格明细!K223 -> -3.3 | J12: =集贸价格明细!M223 -> -29.8 | M12: =集贸价格明细!K224 -> -2.2 | N12: =集贸价格明细!M224 -> -17.8
A13: 46106 | B13: 3月第3周 | C13: =集贸价格明细!H244 -> 26.2 | D13: =集贸价格明细!H245 -> 11.05 | F13: =集贸价格明细!H246 -> 22 | G13: =集贸价格明细!K244 -> -2.6 | H13: =集贸价格明细!M244 -> -30 | I13: =集贸价格明细!K245 -> -2.9 | J13: =集贸价格明细!M245 -> -28 | M13: =集贸价格明细!K246 -> -2.1 | N13: =集贸价格明细!M246 -> -16.5
A14: 46099 | B14: 3月第2周 | C14: =集贸价格明细!H266 -> 26.9 | D14: =集贸价格明细!H267 -> 11.38 | F14: =集贸价格明细!H268 -> 22.48 | G14: =集贸价格明细!K266 -> -2 | H14: =集贸价格明细!M266 -> -27.1 | I14: =集贸价格明细!K267 -> -4.3 | J14: =集贸价格明细!M267 -> -26.1 | M14: =集贸价格明细!K268 -> -2.4 | N14: =集贸价格明细!M268 -> -15
A15: 46091 | B15: 3月第1周 | C15: =集贸价格明细!H288 -> 27.44 | D15: =集贸价格明细!H289 -> 11.89 | F15: =集贸价格明细!H290 -> 23.04 | G15: =集贸价格明细!K288 -> -0.8 | H15: =集贸价格明细!M288 -> -24.9 | I15: =集贸价格明细!K289 -> -4.5 | J15: =集贸价格明细!M289 -> -23.1 | M15: =集贸价格明细!K290 -> -2.1 | N15: =集贸价格明细!M290 -> -13.3
A16: 46084 | B16: 2月第4周 | C16: =集贸价格明细!H310 -> 27.67 | D16: =集贸价格明细!H311 -> 12.45 | F16: =集贸价格明细!H312 -> 23.53 | G16: =集贸价格明细!K310 -> 0.1 | H16: =集贸价格明细!M310 -> -24.2 | I16: =集贸价格明细!K311 -> -1.3 | J16: =集贸价格明细!M311 -> -20.3 | M16: =集贸价格明细!K312 -> -0.8 | N16: =集贸价格明细!M312 -> -12.4
A17: 46083 | B17: 2月第3周 | C17: =集贸价格明细!H332 -> 27.64 | D17: =集贸价格明细!H333 -> 12.62 | F17: =集贸价格明细!H334 -> 23.72 | G17: =集贸价格明细!K332 -> 0.3 | H17: =集贸价格明细!M332 -> -24.3 | I17: =集贸价格明细!K333 -> -2.5 | J17: =集贸价格明细!M333 -> -20.1 | M17: =集贸价格明细!K334 -> -0.3 | N17: =集贸价格明细!M334 -> -12.6
A18: 46079 | B18: 2月第2周 | C18: =集贸价格明细!H354 -> 27.56 | D18: =集贸价格明细!H355 -> 12.94 | F18: =集贸价格明细!H356 -> 23.8 | G18: =集贸价格明细!K354 -> 0.6 | H18: =集贸价格明细!M354 -> -24 | I18: =集贸价格明细!K355 -> -2.5 | J18: =集贸价格明细!M355 -> -18.8 | M18: =集贸价格明细!K356 -> -0.3 | N18: =集贸价格明细!M356 -> -13.7
A19: 46063 | B19: 2月第1周 | C19: =集贸价格明细!H376 -> 27.39 | D19: =集贸价格明细!H377 -> 13.27 | F19: =集贸价格明细!H378 -> 23.87 | G19: =集贸价格明细!K376 -> 1.9 | H19: =集贸价格明细!M376 -> -23 | I19: =集贸价格明细!K377 -> -1.2 | J19: =集贸价格明细!M377 -> -20.3 | M19: =集贸价格明细!K378 -> 0.3 | N19: =集贸价格明细!M378 -> -15.5
A20: 46057 | B20: 1月第5周 | C20: =集贸价格明细!H398 -> 26.87 | D20: =集贸价格明细!H399 -> 13.43 | F20: =集贸价格明细!H400 -> 23.8 | G20: =集贸价格明细!K398 -> 3.5 | H20: =集贸价格明细!M398 -> -23.2 | I20: =集贸价格明细!K399 -> 0.3 | J20: =集贸价格明细!M399 -> -19.5 | M20: =集贸价格明细!K400 -> 1 | N20: =集贸价格明细!M400 -> -15.9
A21: 46049 | B21: 1月第4周 | C21: =集贸价格明细!H420 -> 25.96 | D21: =集贸价格明细!H421 -> 13.39 | F21: =集贸价格明细!H422 -> 23.57 | G21: =集贸价格明细!K420 -> 4.5 | H21: =集贸价格明细!M420 -> -25.2 | I21: =集贸价格明细!K421 -> 2.5 | J21: =集贸价格明细!M421 -> -18.8 | M21: =集贸价格明细!K422 -> 1.6 | N21: =集贸价格明细!M422 -> -15.3
A22: 46045 | B22: 1月第3周 | C22: =集贸价格明细!H442 -> 24.85 | D22: =集贸价格明细!H443 -> 13.06 | F22: =集贸价格明细!H444 -> 23.21 | G22: =集贸价格明细!K442 -> 4.3 | H22: =集贸价格明细!M442 -> -27.1 | I22: =集贸价格明细!K443 -> 1.7 | J22: =集贸价格明细!M443 -> -21.4 | M22: =集贸价格明细!K444 -> 0.9 | N22: =集贸价格明细!M444 -> -16.4
A23: 46035 | B23: 1月第2周 | C23: =集贸价格明细!H464 -> 23.83 | D23: =集贸价格明细!H465 -> 12.84 | F23: =集贸价格明细!H466 -> 23 | G23: =集贸价格明细!K464 -> 1.6 | H23: =集贸价格明细!M464 -> -28.5 | I23: =集贸价格明细!K465 -> 1.8 | J23: =集贸价格明细!M465 -> -23 | M23: =集贸价格明细!K466 -> 0.9 | N23: =集贸价格明细!M466 -> -17.3
A24: 46027 | B24: 1月第1周 | C24: =集贸价格明细!H486 -> 23.45 | D24: =集贸价格明细!H487 -> 12.61 | F24: =集贸价格明细!H488 -> 22.8 | G24: =集贸价格明细!K486 -> 1.3 | H24: =集贸价格明细!M486 -> -28.4 | I24: =集贸价格明细!K487 -> 3.4 | J24: =集贸价格明细!M487 -> -23.9 | M24: =集贸价格明细!K488 -> 1.4 | N24: =集贸价格明细!M488 -> -17.8
A25: 46021 | B25: 12月第4周 | C25: =集贸价格明细!H508 -> 23.14 | D25: =集贸价格明细!H509 -> 12.19 | F25: =集贸价格明细!H510 -> 22.48 | G25: =集贸价格明细!K508 -> -0.6 | H25: =集贸价格明细!M508 -> -29.3 | I25: =集贸价格明细!K509 -> 0.2 | J25: =集贸价格明细!M509 -> -25.9 | M25: =集贸价格明细!K510 -> -0.2 | N25: =集贸价格明细!M510 -> -18.9
A26: 46014 | B26: 12月第3周 | C26: =集贸价格明细!H530 -> 23.28 | D26: =集贸价格明细!H531 -> 12.16 | F26: =集贸价格明细!H532 -> 22.53 | G26: =集贸价格明细!K530 -> -0.6 | H26: =集贸价格明细!M530 -> -29.3 | I26: =集贸价格明细!K531 -> 0 | J26: =集贸价格明细!M531 -> -26.6 | M26: =集贸价格明细!K532 -> -0.3 | N26: =集贸价格明细!M532 -> -19.1
A27: 46008 | B27: 12月第2周 | C27: =集贸价格明细!H552 -> 23.43 | D27: =集贸价格明细!H553 -> 12.13 | F27: =集贸价格明细!H554 -> 22.59 | G27: =集贸价格明细!K552 -> -1.2 | H27: =集贸价格明细!M552 -> -29.7 | I27: =集贸价格明细!K553 -> -0.7 | J27: =集贸价格明细!M553 -> -27.1 | M27: =集贸价格明细!K554 -> -0.7 | N27: =集贸价格明细!M554 -> -19.3
A28: 46000 | B28: 12月第1周 | C28: =集贸价格明细!H574 -> 23.71 | D28: =集贸价格明细!H575 -> 12.21 | F28: =集贸价格明细!H576 -> 22.74 | G28: =集贸价格明细!K574 -> -0.7 | H28: =集贸价格明细!M574 -> -29.6 | I28: =集贸价格明细!K575 -> -1 | J28: =集贸价格明细!M575 -> -27.8 | M28: =集贸价格明细!K576 -> -0.5 | N28: =集贸价格明细!M576 -> -19.3
A29: 45992 | B29: 11月第4周 | C29: =集贸价格明细!H596 -> 23.88 | D29: =集贸价格明细!H597 -> 12.33 | F29: =集贸价格明细!H598 -> 22.86 | G29: =集贸价格明细!K596 -> -1.1 | H29: =集贸价格明细!M596 -> -29.8 | I29: =集贸价格明细!K597 -> -1.4 | J29: =集贸价格明细!M597 -> -27.9 | M29: =集贸价格明细!K598 -> -0.7 | N29: =集贸价格明细!M598 -> -19.3
A30: 45985 | B30: 11月第3周 | C30: =集贸价格明细!H618 -> 24.14 | D30: =集贸价格明细!H619 -> 12.5 | F30: =集贸价格明细!H620 -> 23.02 | G30: =集贸价格明细!K618 -> -1 | H30: =集贸价格明细!M618 -> -29.2 | I30: =集贸价格明细!K619 -> -1.1 | J30: =集贸价格明细!M619 -> -26.6 | M30: =集贸价格明细!K620 -> -0.5 | N30: =集贸价格明细!M620 -> -19.1
A31: 45979 | B31: 11月第2周 | C31: =集贸价格明细!H640 -> 24.39 | D31: =集贸价格明细!H641 -> 12.64 | F31: =集贸价格明细!H642 -> 23.13 | G31: =集贸价格明细!K640 -> -0.8 | H31: =集贸价格明细!M640 -> -29.6 | I31: =集贸价格明细!K641 -> -0.6 | J31: =集贸价格明细!M641 -> -27.4 | M31: =集贸价格明细!K642 -> -0.2 | N31: =集贸价格明细!M642 -> -19.7
A32: 45972 | B32: 11月第1周 | C32: =集贸价格明细!H662 -> 24.59 | D32: =集贸价格明细!H663 -> 12.71 | F32: =集贸价格明细!H664 -> 23.17 | G32: =集贸价格明细!K662 -> -0.8 | H32: =集贸价格明细!M662 -> -29.6 | I32: =集贸价格明细!K663 -> -0.4 | J32: =集贸价格明细!M663 -> -28.6 | M32: =集贸价格明细!K664 -> -0.3 | N32: =集贸价格明细!M664 -> -20.6
A33: 45965 | B33: 10月第4周 | C33: =集贸价格明细!H684 -> 24.78 | D33: =集贸价格明细!H685 -> 12.76 | F33: =集贸价格明细!H686 -> 23.25 | G33: =集贸价格明细!K684 -> -1.4 | H33: =集贸价格明细!M684 -> -29.7 | I33: =集贸价格明细!K685 -> 3.6 | J33: =集贸价格明细!M685 -> -29 | M33: =集贸价格明细!K686 -> 0.6 | N33: =集贸价格明细!M686 -> -20.9
A34: 45959 | B34: 10月第3周 | C34: =集贸价格明细!H706 -> 25.13 | D34: =集贸价格明细!H707 -> 12.32 | F34: =集贸价格明细!H708 -> 23.11 | G34: =集贸价格明细!K706 -> -3.5 | H34: =集贸价格明细!M706 -> -29.5 | I34: =集贸价格明细!K707 -> 0.2 | J34: =集贸价格明细!M707 -> -32.2 | M34: =集贸价格明细!K708 -> -1.1 | N34: =集贸价格明细!M708 -> -22
A35: 45950 | B35: 10月第2周 | C35: =集贸价格明细!H728 -> 26.04 | D35: =集贸价格明细!H729 -> 12.3 | F35: =集贸价格明细!H730 -> 23.37 | G35: =集贸价格明细!K728 -> -4.4 | H35: =集贸价格明细!M728 -> -28.2 | I35: =集贸价格明细!K729 -> -4.7 | J35: =集贸价格明细!M729 -> -33.2 | M35: =集贸价格明细!K730 -> -2.2 | N35: =集贸价格明细!M730 -> -21.9
A36: 45943 | B36: 10月第1周 | C36: =集贸价格明细!H750 -> 27.23 | D36: =集贸价格明细!H751 -> 12.9 | F36: =集贸价格明细!H752 -> 23.89 | G36: =集贸价格明细!K750 -> -3.6 | H36: =集贸价格明细!M750 -> -26.6 | I36: =集贸价格明细!K751 -> -2.8 | J36: =集贸价格明细!M751 -> -29.5 | M36: =集贸价格明细!K752 -> -1.2 | N36: =集贸价格明细!M752 -> -20.6
A37: 45941 | B37: 9月第5周 | C37: =集贸价格明细!H772 -> 28.25 | D37: =集贸价格明细!H773 -> 13.27 | F37: =集贸价格明细!H774 -> 24.17 | G37: =集贸价格明细!K772 -> -2.8 | H37: =集贸价格明细!M772 -> -24.9 | I37: =集贸价格明细!K773 -> -1.8 | J37: =集贸价格明细!M773 -> -27.8 | M37: =集贸价格明细!K774 -> -0.5 | N37: =集贸价格明细!M774 -> -20.1
A38: 45929 | B38: 9月第4周 | C38: =集贸价格明细!H794 -> 29.07 | D38: =集贸价格明细!H795 -> 13.52 | F38: =集贸价格明细!H796 -> 24.29 | G38: =集贸价格明细!K794 -> -3.2 | H38: =集贸价格明细!M794 -> -26.2 | I38: =集贸价格明细!K795 -> -2.4 | J38: =集贸价格明细!M795 -> -28.6 | M38: =集贸价格明细!K796 -> -0.9 | N38: =集贸价格明细!M796 -> -21.2
A39: 45922 | B39: 9月第3周 | C39: =集贸价格明细!H816 -> 30.03 | D39: =集贸价格明细!H817 -> 13.85 | F39: =集贸价格明细!H818 -> 24.51 | G39: =集贸价格明细!K816 -> -3 | H39: =集贸价格明细!M816 -> -26.8 | I39: =集贸价格明细!K817 -> -1.8 | J39: =集贸价格明细!M817 -> -29.3 | M39: =集贸价格明细!K818 -> -0.8 | N39: =集贸价格明细!M818 -> -21.9
A40: 45915 | B40: 9月第2周 | C40: =集贸价格明细!H838 -> 30.96 | D40: =集贸价格明细!H839 -> 14.1 | F40: =集贸价格明细!H840 -> 24.7 | G40: =集贸价格明细!K838 -> -3.3 | H40: =集贸价格明细!M838 -> -26.5 | I40: =集贸价格明细!K839 -> -1.3 | J40: =集贸价格明细!M839 -> -29.7 | M40: =集贸价格明细!K840 -> -0.5 | N40: =集贸价格明细!M840 -> -22.1
...

Sheet 家禽产品价格
C1: 指标价格
A2: 时间 | B2: 周期 | C2: 鸡蛋价格（元/kg） | D2: 鸡蛋(主产省份)价格（元/kg） | E2: 鸡肉价格（元/kg） | F2: 商品代蛋雏鸡价格（元/只） | G2: 商品代肉雏鸡价格（元/只） | H2: 鸡蛋环比 | I2: 鸡蛋同比 | J2: 鸡蛋(主产省份)环比 | K2: 鸡蛋(主产省份)同比 | L2: 鸡肉环比 | M2: 鸡肉同比 | N2: 商品代蛋雏鸡环比 | O2: 商品代蛋雏鸡同比 | P2: 商品代肉雏鸡环比 | Q2: 商品代肉雏鸡同比
A3: 46183 | B3: 6月第1周 | C3: =集贸价格明细!H5 -> 10.87 | D3: =集贸价格明细!H6 -> 10.6 | E3: =集贸价格明细!H7 -> 22.21 | F3: =集贸价格明细!H8 -> 3.89 | G3: =集贸价格明细!H9 -> 3.49 | H3: =集贸价格明细!K5 -> 5.9 | I3: =集贸价格明细!M5 -> 21.3 | J3: =集贸价格明细!K6 -> 10 | K3: =集贸价格明细!M6 -> 41.7 | L3: =集贸价格明细!K7 -> 0 | M3: =集贸价格明细!M7 -> -2.4 | N3: =集贸价格明细!K8 -> 1.3 | O3: =集贸价格明细!M8 -> -3.7 | P3: =集贸价格明细!K9 -> 0.3 | Q3: =集贸价格明细!M9 -> 2.9
A4: 46176 | B4: 5月第4周 | C4: =集贸价格明细!H27 -> 10.26 | D4: =集贸价格明细!H28 -> 9.64 | E4: =集贸价格明细!H29 -> 22.2 | F4: =集贸价格明细!H30 -> 3.84 | G4: =集贸价格明细!H31 -> 3.48 | H4: =集贸价格明细!K27 -> 2.7 | I4: =集贸价格明细!M27 -> 13.1 | J4: =集贸价格明细!K28 -> 3.7 | K4: =集贸价格明细!M28 -> 25.7 | L4: =集贸价格明细!K29 -> 0 | M4: =集贸价格明细!M29 -> -2.6 | N4: =集贸价格明细!K30 -> 1.1 | O4: =集贸价格明细!M30 -> -6.1 | P4: =集贸价格明细!K31 -> 0.6 | Q4: =集贸价格明细!M31 -> 2.4
A5: 46168 | B5: 5月第3周 | C5: =集贸价格明细!H49 -> 9.99 | D5: =集贸价格明细!H50 -> 9.3 | E5: =集贸价格明细!H51 -> 22.2 | F5: =集贸价格明细!H52 -> 3.8 | G5: =集贸价格明细!H53 -> 3.46 | H5: =集贸价格明细!K49 -> 2.4 | I5: =集贸价格明细!M49 -> 8.9 | J5: =集贸价格明细!K50 -> 2.3 | K5: =集贸价格明细!M50 -> 18.9 | L5: =集贸价格明细!K51 -> 0.4 | M5: =集贸价格明细!M51 -> -2.7 | N5: =集贸价格明细!K52 -> 0.8 | O5: =集贸价格明细!M52 -> -7.8 | P5: =集贸价格明细!K53 -> 1.2 | Q5: =集贸价格明细!M53 -> 1.2
A6: 46162 | B6: 5月第2周 | C6: =集贸价格明细!H71 -> 9.76 | D6: =集贸价格明细!H72 -> 9.09 | E6: =集贸价格明细!H73 -> 22.12 | F6: =集贸价格明细!H74 -> 3.77 | G6: =集贸价格明细!H75 -> 3.42 | H6: =集贸价格明细!K71 -> 2.8 | I6: =集贸价格明细!M71 -> 5.6 | J6: =集贸价格明细!K72 -> 4.1 | K6: =集贸价格明细!M72 -> 15.8 | L6: =集贸价格明细!K73 -> 0.2 | M6: =集贸价格明细!M73 -> -3.1 | N6: =集贸价格明细!K74 -> 0.5 | O6: =集贸价格明细!M74 -> -8.7 | P6: =集贸价格明细!K75 -> 0 | Q6: =集贸价格明细!M75 -> -0.9
A7: 46156 | B7: 5月第1周 | C7: =集贸价格明细!H93 -> 9.49 | D7: =集贸价格明细!H94 -> 8.73 | E7: =集贸价格明细!H95 -> 22.08 | F7: =集贸价格明细!H96 -> 3.75 | G7: =集贸价格明细!H97 -> 3.42 | H7: =集贸价格明细!K93 -> 2 | I7: =集贸价格明细!M93 -> 2 | J7: =集贸价格明细!K94 -> 2.9 | K7: =集贸价格明细!M94 -> 10.6 | L7: =集贸价格明细!K95 -> 0 | M7: =集贸价格明细!M95 -> -3.5 | N7: =集贸价格明细!K96 -> 0.5 | O7: =集贸价格明细!M96 -> -9.9 | P7: =集贸价格明细!K97 -> 0.3 | Q7: =集贸价格明细!M97 -> -1.2
A8: 46151 | B8: 4月第5周 | C8: =集贸价格明细!H115 -> 9.3 | D8: =集贸价格明细!H116 -> 8.48 | E8: =集贸价格明细!H117 -> 22.07 | F8: =集贸价格明细!H118 -> 3.73 | G8: =集贸价格明细!H119 -> 3.41 | H8: =集贸价格明细!K115 -> 1 | I8: =集贸价格明细!M115 -> -1.3 | J8: =集贸价格明细!K116 -> 1.7 | K8: =集贸价格明细!M116 -> 5.3 | L8: =集贸价格明细!K117 -> 0.2 | M8: =集贸价格明细!M117 -> -3.7 | N8: =集贸价格明细!K118 -> 0.3 | O8: =集贸价格明细!M118 -> -10.6 | P8: =集贸价格明细!K119 -> 0 | Q8: =集贸价格明细!M119 -> -1.7
A9: 46151 | B9: 4月第4周 | C9: =集贸价格明细!H137 -> 9.21 | D9: =集贸价格明细!H138 -> 8.34 | E9: =集贸价格明细!H139 -> 22.03 | F9: =集贸价格明细!H140 -> 3.72 | G9: =集贸价格明细!H141 -> 3.41 | H9: =集贸价格明细!K137 -> 2.4 | I9: =集贸价格明细!M137 -> -3 | J9: =集贸价格明细!K138 -> 3.9 | K9: =集贸价格明细!M138 -> 2.1 | L9: =集贸价格明细!K139 -> 0.1 | M9: =集贸价格明细!M139 -> -3.8 | N9: =集贸价格明细!K140 -> 0.5 | O9: =集贸价格明细!M140 -> -10.8 | P9: =集贸价格明细!K141 -> 0 | Q9: =集贸价格明细!M141 -> -1.7
A10: 46134 | B10: 4月第3周 | C10: =集贸价格明细!H159 -> 8.99 | D10: =集贸价格明细!H160 -> 8.03 | E10: =集贸价格明细!H161 -> 22.01 | F10: =集贸价格明细!H162 -> 3.7 | G10: =集贸价格明细!H163 -> 3.41 | H10: =集贸价格明细!K159 -> 2.2 | I10: =集贸价格明细!M159 -> -4.2 | J10: =集贸价格明细!K160 -> 5.1 | K10: =集贸价格明细!M160 -> 0.5 | L10: =集贸价格明细!K161 -> -0.5 | M10: =集贸价格明细!M161 -> -4 | N10: =集贸价格明细!K162 -> 0 | O10: =集贸价格明细!M162 -> -12.1 | P10: =集贸价格明细!K163 -> 0 | Q10: =集贸价格明细!M163 -> -1.7
A11: 46127 | B11: 4月第2周 | C11: =集贸价格明细!H181 -> 8.8 | D11: =集贸价格明细!H182 -> 7.64 | E11: =集贸价格明细!H183 -> 22.11 | F11: =集贸价格明细!H184 -> 3.7 | G11: =集贸价格明细!H185 -> 3.41 | H11: =集贸价格明细!K181 -> 0.1 | I11: =集贸价格明细!M181 -> -5.3 | J11: =集贸价格明细!K182 -> 1.2 | K11: =集贸价格明细!M182 -> -2.2 | L11: =集贸价格明细!K183 -> -0.5 | M11: =集贸价格明细!M183 -> -3.6 | N11: =集贸价格明细!K184 -> 0 | O11: =集贸价格明细!M184 -> -11.1 | P11: =集贸价格明细!K185 -> -0.3 | Q11: =集贸价格明细!M185 -> -1.4
A12: 46120 | B12: 4月第1周 | C12: =集贸价格明细!H203 -> 8.79 | D12: =集贸价格明细!H204 -> 7.55 | E12: =集贸价格明细!H205 -> 22.21 | F12: =集贸价格明细!H206 -> 3.7 | G12: =集贸价格明细!H207 -> 3.42 | H12: =集贸价格明细!K203 -> 0.7 | I12: =集贸价格明细!M203 -> -5.9 | J12: =集贸价格明细!K204 -> 1.9 | K12: =集贸价格明细!M204 -> -3.6 | L12: =集贸价格明细!K205 -> -0.3 | M12: =集贸价格明细!M205 -> -3.2 | N12: =集贸价格明细!K206 -> 0.3 | O12: =集贸价格明细!M206 -> -10.8 | P12: =集贸价格明细!K207 -> 0.6 | Q12: =集贸价格明细!M207 -> -1.2
A13: 46111 | B13: 3月第4周 | C13: =集贸价格明细!H225 -> 8.73 | D13: =集贸价格明细!H226 -> 7.41 | E13: =集贸价格明细!H227 -> 22.28 | F13: =集贸价格明细!H228 -> 3.69 | G13: =集贸价格明细!H229 -> 3.4 | H13: =集贸价格明细!K225 -> 0.3 | I13: =集贸价格明细!M225 -> -7.5 | J13: =集贸价格明细!K226 -> 1.1 | K13: =集贸价格明细!M226 -> -6.7 | L13: =集贸价格明细!K227 -> -0.5 | M13: =集贸价格明细!M227 -> -3.1 | N13: =集贸价格明细!K228 -> 0 | O13: =集贸价格明细!M228 -> -11.3 | P13: =集贸价格明细!K229 -> 0 | Q13: =集贸价格明细!M229 -> -2
A14: 46106 | B14: 3月第3周 | C14: =集贸价格明细!H247 -> 8.7 | D14: =集贸价格明细!H248 -> 7.33 | E14: =集贸价格明细!H249 -> 22.4 | F14: =集贸价格明细!H250 -> 3.69 | G14: =集贸价格明细!H251 -> 3.4 | H14: =集贸价格明细!K247 -> -0.2 | I14: =集贸价格明细!M247 -> -8.9 | J14: =集贸价格明细!K248 -> 0 | K14: =集贸价格明细!M248 -> -8.6 | L14: =集贸价格明细!K249 -> -0.6 | M14: =集贸价格明细!M249 -> -2.8 | N14: =集贸价格明细!K250 -> 0 | O14: =集贸价格明细!M250 -> -11.3 | P14: =集贸价格明细!K251 -> 0.3 | Q14: =集贸价格明细!M251 -> -1.2
A15: 46099 | B15: 3月第2周 | C15: =集贸价格明细!H269 -> 8.72 | D15: =集贸价格明细!H270 -> 7.33 | E15: =集贸价格明细!H271 -> 22.54 | F15: =集贸价格明细!H272 -> 3.69 | G15: =集贸价格明细!H273 -> 3.39 | H15: =集贸价格明细!K269 -> -1 | I15: =集贸价格明细!M269 -> -9.9 | J15: =集贸价格明细!K270 -> -1.7 | K15: =集贸价格明细!M270 -> -10.6 | L15: =集贸价格明细!K271 -> -0.5 | M15: =集贸价格明细!M271 -> -2.5 | N15: =集贸价格明细!K272 -> 0.8 | O15: =集贸价格明细!M272 -> -11.1 | P15: =集贸价格明细!K273 -> 0.3 | Q15: =集贸价格明细!M273 -> -0.6
A16: 46091 | B16: 3月第1周 | C16: =集贸价格明细!H291 -> 8.81 | D16: =集贸价格明细!H292 -> 7.46 | E16: =集贸价格明细!H293 -> 22.66 | F16: =集贸价格明细!H294 -> 3.66 | G16: =集贸价格明细!H295 -> 3.38 | H16: =集贸价格明细!K291 -> -2 | I16: =集贸价格明细!M291 -> -9.9 | J16: =集贸价格明细!K292 -> -2.7 | K16: =集贸价格明细!M292 -> -10.1 | L16: =集贸价格明细!K293 -> -0.7 | M16: =集贸价格明细!M293 -> -2.1 | N16: =集贸价格明细!K294 -> 0.3 | O16: =集贸价格明细!M294 -> -11.4 | P16: =集贸价格明细!K295 -> 0.3 | Q16: =集贸价格明细!M295 -> -0.3
A17: 46084 | B17: 2月第4周 | C17: =集贸价格明细!H313 -> 8.99 | D17: =集贸价格明细!H314 -> 7.67 | E17: =集贸价格明细!H315 -> 22.83 | F17: =集贸价格明细!H316 -> 3.65 | G17: =集贸价格明细!H317 -> 3.37 | H17: =集贸价格明细!K313 -> -0.9 | I17: =集贸价格明细!M313 -> -8.3 | J17: =集贸价格明细!K314 -> -1.8 | K17: =集贸价格明细!M314 -> -6.7 | L17: =集贸价格明细!K315 -> -0.3 | M17: =集贸价格明细!M315 -> -1.6 | N17: =集贸价格明细!K316 -> 0.6 | O17: =集贸价格明细!M316 -> -11.6 | P17: =集贸价格明细!K317 -> 0.6 | Q17: =集贸价格明细!M317 -> -0.9
A18: 46083 | B18: 2月第3周 | C18: =集贸价格明细!H335 -> 9.07 | D18: =集贸价格明细!H336 -> 7.81 | E18: =集贸价格明细!H337 -> 22.91 | F18: =集贸价格明细!H338 -> 3.63 | G18: =集贸价格明细!H339 -> 3.35 | H18: =集贸价格明细!K335 -> -2.5 | I18: =集贸价格明细!M335 -> -8.9 | J18: =集贸价格明细!K336 -> -5.8 | K18: =集贸价格明细!M336 -> -6.6 | L18: =集贸价格明细!K337 -> 0.1 | M18: =集贸价格明细!M337 -> -1.8 | N18: =集贸价格明细!K338 -> 0.3 | O18: =集贸价格明细!M338 -> -11.9 | P18: =集贸价格明细!K339 -> 1.2 | Q18: =集贸价格明细!M339 -> -0.9
A19: 46079 | B19: 2月第2周 | C19: =集贸价格明细!H357 -> 9.3 | D19: =集贸价格明细!H358 -> 8.29 | E19: =集贸价格明细!H359 -> 22.89 | F19: =集贸价格明细!H360 -> 3.62 | G19: =集贸价格明细!H361 -> 3.31 | H19: =集贸价格明细!K357 -> -0.6 | I19: =集贸价格明细!M357 -> -9.5 | J19: =集贸价格明细!K358 -> -1.7 | K19: =集贸价格明细!M358 -> -5.3 | L19: =集贸价格明细!K359 -> 1 | M19: =集贸价格明细!M359 -> -2.8 | N19: =集贸价格明细!K360 -> 0.6 | O19: =集贸价格明细!M360 -> -11.9 | P19: =集贸价格明细!K361 -> 0.6 | Q19: =集贸价格明细!M361 -> -2.4
A20: 46063 | B20: 2月第1周 | C20: =集贸价格明细!H379 -> 9.36 | D20: =集贸价格明细!H380 -> 8.43 | E20: =集贸价格明细!H381 -> 22.67 | F20: =集贸价格明细!H382 -> 3.6 | G20: =集贸价格明细!H383 -> 3.29 | H20: =集贸价格明细!K379 -> 0.8 | I20: =集贸价格明细!M379 -> -12.8 | J20: =集贸价格明细!K380 -> 1.1 | K20: =集贸价格明细!M380 -> -10.4 | L20: =集贸价格明细!K381 -> 0.4 | M20: =集贸价格明细!M381 -> -4.8 | N20: =集贸价格明细!K382 -> 0.6 | O20: =集贸价格明细!M382 -> -12.2 | P20: =集贸价格明细!K383 -> -0.3 | Q20: =集贸价格明细!M383 -> -4.4
A21: 46057 | B21: 1月第5周 | C21: =集贸价格明细!H401 -> 9.29 | D21: =集贸价格明细!H402 -> 8.34 | E21: =集贸价格明细!H403 -> 22.59 | F21: =集贸价格明细!H404 -> 3.58 | G21: =集贸价格明细!H405 -> 3.3 | H21: =集贸价格明细!K401 -> 2.9 | I21: =集贸价格明细!M401 -> -15.5 | J21: =集贸价格明细!K402 -> 4.9 | K21: =集贸价格明细!M402 -> -15.7 | L21: =集贸价格明细!K403 -> 0.5 | M21: =集贸价格明细!M403 -> -5.6 | N21: =集贸价格明细!K404 -> 0.8 | O21: =集贸价格明细!M404 -> -12.7 | P21: =集贸价格明细!K405 -> 0.3 | Q21: =集贸价格明细!M405 -> -4.1
A22: 46049 | B22: 1月第4周 | C22: =集贸价格明细!H423 -> 9.03 | D22: =集贸价格明细!H424 -> 7.95 | E22: =集贸价格明细!H425 -> 22.47 | F22: =集贸价格明细!H426 -> 3.55 | G22: =集贸价格明细!H427 -> 3.29 | H22: =集贸价格明细!K423 -> 2.7 | I22: =集贸价格明细!M423 -> -17.9 | J22: =集贸价格明细!K424 -> 5 | K22: =集贸价格明细!M424 -> -19.9 | L22: =集贸价格明细!K425 -> 0.4 | M22: =集贸价格明细!M425 -> -5.1 | N22: =集贸价格明细!K426 -> 0.9 | O22: =集贸价格明细!M426 -> -13.4 | P22: =集贸价格明细!K427 -> -1.5 | Q22: =集贸价格明细!M427 -> -4.1
A23: 46045 | B23: 1月第3周 | C23: =集贸价格明细!H445 -> 8.79 | D23: =集贸价格明细!H446 -> 7.57 | E23: =集贸价格明细!H447 -> 22.37 | F23: =集贸价格明细!H448 -> 3.52 | G23: =集贸价格明细!H449 -> 3.34 | H23: =集贸价格明细!K445 -> 1.7 | I23: =集贸价格明细!M445 -> -20.3 | J23: =集贸价格明细!K446 -> 3.7 | K23: =集贸价格明细!M446 -> -24.6 | L23: =集贸价格明细!K447 -> 0.3 | M23: =集贸价格明细!M447 -> -5.1 | N23: =集贸价格明细!K448 -> 0.9 | O23: =集贸价格明细!M448 -> -13.9 | P23: =集贸价格明细!K449 -> 0 | Q23: =集贸价格明细!M449 -> -3.5
A24: 46035 | B24: 1月第2周 | C24: =集贸价格明细!H467 -> 8.64 | D24: =集贸价格明细!H468 -> 7.3 | E24: =集贸价格明细!H469 -> 22.31 | F24: =集贸价格明细!H470 -> 3.49 | G24: =集贸价格明细!H471 -> 3.34 | H24: =集贸价格明细!K467 -> 0.6 | I24: =集贸价格明细!M467 -> -21.5 | J24: =集贸价格明细!K468 -> 1.4 | K24: =集贸价格明细!M468 -> -26.8 | L24: =集贸价格明细!K469 -> 0 | M24: =集贸价格明细!M469 -> -5.2 | N24: =集贸价格明细!K470 -> 0.6 | O24: =集贸价格明细!M470 -> -14.5 | P24: =集贸价格明细!K471 -> -1.2 | Q24: =集贸价格明细!M471 -> -3.7
A25: 46027 | B25: 1月第1周 | C25: =集贸价格明细!H489 -> 8.59 | D25: =集贸价格明细!H490 -> 7.2 | E25: =集贸价格明细!H491 -> 22.3 | F25: =集贸价格明细!H492 -> 3.47 | G25: =集贸价格明细!H493 -> 3.38 | H25: =集贸价格明细!K489 -> 0.2 | I25: =集贸价格明细!M489 -> -22.5 | J25: =集贸价格明细!K490 -> 0.6 | K25: =集贸价格明细!M490 -> -28.4 | L25: =集贸价格明细!K491 -> 0 | M25: =集贸价格明细!M491 -> -5 | N25: =集贸价格明细!K492 -> 0 | O25: =集贸价格明细!M492 -> -14.5 | P25: =集贸价格明细!K493 -> -0.9 | Q25: =集贸价格明细!M493 -> -3.2
A26: 46021 | B26: 12月第4周 | C26: =集贸价格明细!H511 -> 8.57 | D26: =集贸价格明细!H512 -> 7.16 | E26: =集贸价格明细!H513 -> 22.29 | F26: =集贸价格明细!H514 -> 3.47 | G26: =集贸价格明细!H515 -> 3.41 | H26: =集贸价格明细!K511 -> -0.5 | I26: =集贸价格明细!M511 -> -23 | J26: =集贸价格明细!K512 -> -0.8 | K26: =集贸价格明细!M512 -> -29.2 | L26: =集贸价格明细!K513 -> 0.1 | M26: =集贸价格明细!M513 -> -5.1 | N26: =集贸价格明细!K514 -> -0.3 | O26: =集贸价格明细!M514 -> -14.5 | P26: =集贸价格明细!K515 -> -0.3 | Q26: =集贸价格明细!M515 -> -5.3
A27: 46014 | B27: 12月第3周 | C27: =集贸价格明细!H533 -> 8.61 | D27: =集贸价格明细!H534 -> 7.22 | E27: =集贸价格明细!H535 -> 22.26 | F27: =集贸价格明细!H536 -> 3.48 | G27: =集贸价格明细!H537 -> 3.42 | H27: =集贸价格明细!K533 -> 0.1 | I27: =集贸价格明细!M533 -> -22.7 | J27: =集贸价格明细!K534 -> 0.4 | K27: =集贸价格明细!M534 -> -28.7 | L27: =集贸价格明细!K535 -> 0 | M27: =集贸价格明细!M535 -> -5.2 | N27: =集贸价格明细!K536 -> -0.3 | O27: =集贸价格明细!M536 -> -14.1 | P27: =集贸价格明细!K537 -> 0.3 | Q27: =集贸价格明细!M537 -> -4.7
A28: 46008 | B28: 12月第2周 | C28: =集贸价格明细!H555 -> 8.6 | D28: =集贸价格明细!H556 -> 7.19 | E28: =集贸价格明细!H557 -> 22.25 | F28: =集贸价格明细!H558 -> 3.49 | G28: =集贸价格明细!H559 -> 3.41 | H28: =集贸价格明细!K555 -> -0.1 | I28: =集贸价格明细!M555 -> -22.7 | J28: =集贸价格明细!K556 -> 0.1 | K28: =集贸价格明细!M556 -> -28.7 | L28: =集贸价格明细!K557 -> -0.2 | M28: =集贸价格明细!M557 -> -5.2 | N28: =集贸价格明细!K558 -> 0 | O28: =集贸价格明细!M558 -> -13.2 | P28: =集贸价格明细!K559 -> 0 | Q28: =集贸价格明细!M559 -> -6.8
A29: 46000 | B29: 12月第1周 | C29: =集贸价格明细!H577 -> 8.61 | D29: =集贸价格明细!H578 -> 7.18 | E29: =集贸价格明细!H579 -> 22.3 | F29: =集贸价格明细!H580 -> 3.49 | G29: =集贸价格明细!H581 -> 3.41 | H29: =集贸价格明细!K577 -> 0.2 | I29: =集贸价格明细!M577 -> -22.4 | J29: =集贸价格明细!K578 -> 1.3 | K29: =集贸价格明细!M578 -> -28.5 | L29: =集贸价格明细!K579 -> -0.1 | M29: =集贸价格明细!M579 -> -5.1 | N29: =集贸价格明细!K580 -> 0 | O29: =集贸价格明细!M580 -> -12.8 | P29: =集贸价格明细!K581 -> 0 | Q29: =集贸价格明细!M581 -> -8.3
A30: 45992 | B30: 11月第4周 | C30: =集贸价格明细!H599 -> 8.59 | D30: =集贸价格明细!H600 -> 7.09 | E30: =集贸价格明细!H601 -> 22.33 | F30: =集贸价格明细!H602 -> 3.49 | G30: =集贸价格明细!H603 -> 3.41 | H30: =集贸价格明细!K599 -> -0.2 | I30: =集贸价格明细!M599 -> -22 | J30: =集贸价格明细!K600 -> 0 | K30: =集贸价格明细!M600 -> -28.4 | L30: =集贸价格明细!K601 -> 0 | M30: =集贸价格明细!M601 -> -5.1 | N30: =集贸价格明细!K602 -> -0.3 | O30: =集贸价格明细!M602 -> -12.5 | P30: =集贸价格明细!K603 -> 0 | Q30: =集贸价格明细!M603 -> -9.1
A31: 45985 | B31: 11月第3周 | C31: =集贸价格明细!H621 -> 8.61 | D31: =集贸价格明细!H622 -> 7.09 | E31: =集贸价格明细!H623 -> 22.34 | F31: =集贸价格明细!H624 -> 3.5 | G31: =集贸价格明细!H625 -> 3.41 | H31: =集贸价格明细!K621 -> -0.6 | I31: =集贸价格明细!M621 -> -22.4 | J31: =集贸价格明细!K622 -> -1 | K31: =集贸价格明细!M622 -> -29.2 | L31: =集贸价格明细!K623 -> -0.1 | M31: =集贸价格明细!M623 -> -5.2 | N31: =集贸价格明细!K624 -> -0.8 | O31: =集贸价格明细!M624 -> -11.8 | P31: =集贸价格明细!K625 -> -0.6 | Q31: =集贸价格明细!M625 -> -8.8
A32: 45979 | B32: 11月第2周 | C32: =集贸价格明细!H643 -> 8.66 | D32: =集贸价格明细!H644 -> 7.16 | E32: =集贸价格明细!H645 -> 22.37 | F32: =集贸价格明细!H646 -> 3.53 | G32: =集贸价格明细!H647 -> 3.43 | H32: =集贸价格明细!K643 -> -0.1 | I32: =集贸价格明细!M643 -> -22.9 | J32: =集贸价格明细!K644 -> 0.3 | K32: =集贸价格明细!M644 -> -30.1 | L32: =集贸价格明细!K645 -> 0.2 | M32: =集贸价格明细!M645 -> -5.1 | N32: =集贸价格明细!K646 -> -0.6 | O32: =集贸价格明细!M646 -> -10.6 | P32: =集贸价格明细!K647 -> 0 | Q32: =集贸价格明细!M647 -> -7.8
A33: 45972 | B33: 11月第1周 | C33: =集贸价格明细!H665 -> 8.67 | D33: =集贸价格明细!H666 -> 7.14 | E33: =集贸价格明细!H667 -> 22.33 | F33: =集贸价格明细!H668 -> 3.55 | G33: =集贸价格明细!H669 -> 3.43 | H33: =集贸价格明细!K665 -> -0.7 | I33: =集贸价格明细!M665 -> -23.4 | J33: =集贸价格明细!K666 -> -1.7 | K33: =集贸价格明细!M666 -> -31.1 | L33: =集贸价格明细!K667 -> 0 | M33: =集贸价格明细!M667 -> -5.4 | N33: =集贸价格明细!K668 -> -0.6 | O33: =集贸价格明细!M668 -> -10.1 | P33: =集贸价格明细!K669 -> 0 | Q33: =集贸价格明细!M669 -> -8.3
A34: 45965 | B34: 10月第4周 | C34: =集贸价格明细!H687 -> 8.73 | D34: =集贸价格明细!H688 -> 7.26 | E34: =集贸价格明细!H689 -> 22.33 | F34: =集贸价格明细!H690 -> 3.57 | G34: =集贸价格明细!H691 -> 3.43 | H34: =集贸价格明细!K687 -> -0.1 | I34: =集贸价格明细!M687 -> -23.4 | J34: =集贸价格明细!K688 -> -0.1 | K34: =集贸价格明细!M688 -> -30.9 | L34: =集贸价格明细!K689 -> 0 | M34: =集贸价格明细!M689 -> -5.4 | N34: =集贸价格明细!K690 -> -0.8 | O34: =集贸价格明细!M690 -> -9.8 | P34: =集贸价格明细!K691 -> 0.9 | Q34: =集贸价格明细!M691 -> -8.3
A35: 45959 | B35: 10月第3周 | C35: =集贸价格明细!H709 -> 8.74 | D35: =集贸价格明细!H710 -> 7.27 | E35: =集贸价格明细!H711 -> 22.33 | F35: =集贸价格明细!H712 -> 3.6 | G35: =集贸价格明细!H713 -> 3.4 | H35: =集贸价格明细!K709 -> -1.4 | I35: =集贸价格明细!M709 -> -23.1 | J35: =集贸价格明细!K710 -> -2.3 | K35: =集贸价格明细!M710 -> -30.3 | L35: =集贸价格明细!K711 -> -0.6 | M35: =集贸价格明细!M711 -> -5.7 | N35: =集贸价格明细!K712 -> -1.1 | O35: =集贸价格明细!M712 -> -8.6 | P35: =集贸价格明细!K713 -> 0 | Q35: =集贸价格明细!M713 -> -9.1
A36: 45950 | B36: 10月第2周 | C36: =集贸价格明细!H731 -> 8.86 | D36: =集贸价格明细!H732 -> 7.44 | E36: =集贸价格明细!H733 -> 22.46 | F36: =集贸价格明细!H734 -> 3.64 | G36: =集贸价格明细!H735 -> 3.4 | H36: =集贸价格明细!K731 -> -3 | I36: =集贸价格明细!M731 -> -21 | J36: =集贸价格明细!K732 -> -5.6 | K36: =集贸价格明细!M732 -> -27 | L36: =集贸价格明细!K733 -> -0.6 | M36: =集贸价格明细!M733 -> -5.2 | N36: =集贸价格明细!K734 -> -1.6 | O36: =集贸价格明细!M734 -> -7.4 | P36: =集贸价格明细!K735 -> -1.2 | Q36: =集贸价格明细!M735 -> -8.8
A37: 45943 | B37: 10月第1周 | C37: =集贸价格明细!H753 -> 9.13 | D37: =集贸价格明细!H754 -> 7.88 | E37: =集贸价格明细!H755 -> 22.59 | F37: =集贸价格明细!H756 -> 3.7 | G37: =集贸价格明细!H757 -> 3.44 | H37: =集贸价格明细!K753 -> -2.2 | I37: =集贸价格明细!M753 -> -19 | J37: =集贸价格明细!K754 -> -4.5 | K37: =集贸价格明细!M754 -> -22.7 | L37: =集贸价格明细!K755 -> -0.1 | M37: =集贸价格明细!M755 -> -4.8 | N37: =集贸价格明细!K756 -> -0.8 | O37: =集贸价格明细!M756 -> -5.4 | P37: =集贸价格明细!K757 -> -0.3 | Q37: =集贸价格明细!M757 -> -7
A38: 45941 | B38: 9月第5周 | C38: =集贸价格明细!H775 -> 9.34 | D38: =集贸价格明细!H776 -> 8.25 | E38: =集贸价格明细!H777 -> 22.62 | F38: =集贸价格明细!H778 -> 3.73 | G38: =集贸价格明细!H779 -> 3.45 | H38: =集贸价格明细!K775 -> 0 | I38: =集贸价格明细!M775 -> -17.6 | J38: =集贸价格明细!K776 -> -0.1 | K38: =集贸价格明细!M776 -> -20 | L38: =集贸价格明细!K777 -> 0.2 | M38: =集贸价格明细!M777 -> -4.8 | N38: =集贸价格明细!K778 -> -0.3 | O38: =集贸价格明细!M778 -> -4.6 | P38: =集贸价格明细!K779 -> 0 | Q38: =集贸价格明细!M779 -> -6
A39: 45929 | B39: 9月第4周 | C39: =集贸价格明细!H797 -> 9.34 | D39: =集贸价格明细!H798 -> 8.26 | E39: =集贸价格明细!H799 -> 22.58 | F39: =集贸价格明细!H800 -> 3.74 | G39: =集贸价格明细!H801 -> 3.45 | H39: =集贸价格明细!K797 -> 1.2 | I39: =集贸价格明细!M797 -> -19.7 | J39: =集贸价格明细!K798 -> 1.8 | K39: =集贸价格明细!M798 -> -24.3 | L39: =集贸价格明细!K799 -> 0.3 | M39: =集贸价格明细!M799 -> -5.2 | N39: =集贸价格明细!K800 -> 0 | O39: =集贸价格明细!M800 -> -3.9 | P39: =集贸价格明细!K801 -> 0 | Q39: =集贸价格明细!M801 -> -4.7
A40: 45922 | B40: 9月第3周 | C40: =集贸价格明细!H819 -> 9.23 | D40: =集贸价格明细!H820 -> 8.11 | E40: =集贸价格明细!H821 -> 22.52 | F40: =集贸价格明细!H822 -> 3.74 | G40: =集贸价格明细!H823 -> 3.45 | H40: =集贸价格明细!K819 -> 2.6 | I40: =集贸价格明细!M819 -> -21.8 | J40: =集贸价格明细!K820 -> 4.6 | K40: =集贸价格明细!M820 -> -28.2 | L40: =集贸价格明细!K821 -> 0 | M40: =集贸价格明细!M821 -> -5.8 | N40: =集贸价格明细!K822 -> 0 | O40: =集贸价格明细!M822 -> -3.9 | P40: =集贸价格明细!K823 -> -0.6 | Q40: =集贸价格明细!M823 -> -4.4
...

Sheet 牛羊产品价格
C1: 指标价格
A2: 时间 | B2: 周期 | C2: 牛肉价格（元/kg） | D2: 牛肉(主产省份)价格（元/kg） | E2: 活牛(主产省份)价格（元/kg） | F2: 羊肉价格（元/kg） | G2: 羊肉(主产省份)价格（元/kg） | H2: 活羊(主产省份)价格（元/kg） | I2: 牛肉环比 | J2: 牛肉同比 | K2: 牛肉(主产省份)环比 | L2: 牛肉(主产省份)同比 | M2: 活牛(主产省份)环比 | N2: 活牛(主产省份)同比 | O2: 羊肉环比 | P2: 羊肉同比 | Q2: 羊肉(主产省份)环比 | R2: 羊肉(主产省份)同比 | S2: 活羊(主产省份)环比 | T2: 活羊(主产省份)同比
A3: 46183 | B3: 6月第1周 | C3: =集贸价格明细!H10 -> 73.39 | D3: =集贸价格明细!H11 -> 67.78 | E3: =集贸价格明细!H12 -> 28.26 | F3: =集贸价格明细!H13 -> 72.66 | G3: =集贸价格明细!H14 -> 71.1 | H3: =集贸价格明细!H15 -> 30.81 | I3: =集贸价格明细!K10 -> 0.1 | J3: =集贸价格明细!M10 -> 5 | K3: =集贸价格明细!K11 -> -0.1 | L3: =集贸价格明细!M11 -> 0 | M3: =集贸价格明细!K12 -> 0 | N3: =集贸价格明细!M12 -> 5.5 | O3: =集贸价格明细!K13 -> 0 | P3: =集贸价格明细!M13 -> 4.7 | Q3: =集贸价格明细!K14 -> 0 | R3: =集贸价格明细!M14 -> 0 | S3: =集贸价格明细!K15 -> -0.1 | T3: =集贸价格明细!M15 -> 6.1
A4: 46176 | B4: 5月第4周 | C4: =集贸价格明细!H32 -> 73.34 | D4: =集贸价格明细!H33 -> 67.84 | E4: =集贸价格明细!H34 -> 28.33 | F4: =集贸价格明细!H35 -> 72.64 | G4: =集贸价格明细!H36 -> 71.09 | H4: =集贸价格明细!H37 -> 30.84 | I4: =集贸价格明细!K32 -> 0.1 | J4: =集贸价格明细!M32 -> 5 | K4: =集贸价格明细!K33 -> 0.1 | L4: =集贸价格明细!M33 -> 0 | M4: =集贸价格明细!K34 -> 0 | N4: =集贸价格明细!M34 -> 5.6 | O4: =集贸价格明细!K35 -> 0.1 | P4: =集贸价格明细!M35 -> 4.6 | Q4: =集贸价格明细!K36 -> 0.1 | R4: =集贸价格明细!M36 -> 0 | S4: =集贸价格明细!K37 -> 0.1 | T4: =集贸价格明细!M37 -> 5.7
A5: 46168 | B5: 5月第3周 | C5: =集贸价格明细!H54 -> 73.28 | D5: =集贸价格明细!H55 -> 67.79 | E5: =集贸价格明细!H56 -> 28.29 | F5: =集贸价格明细!H57 -> 72.6 | G5: =集贸价格明细!H58 -> 70.99 | H5: =集贸价格明细!H59 -> 30.82 | I5: =集贸价格明细!K54 -> 0.1 | J5: =集贸价格明细!M54 -> 4.9 | K5: =集贸价格明细!K55 -> 0.1 | L5: =集贸价格明细!M55 -> 0 | M5: =集贸价格明细!K56 -> 0 | N5: =集贸价格明细!M56 -> 5.2 | O5: =集贸价格明细!K57 -> 0.1 | P5: =集贸价格明细!M57 -> 4.4 | Q5: =集贸价格明细!K58 -> -0.1 | R5: =集贸价格明细!M58 -> 0 | S5: =集贸价格明细!K59 -> -0.1 | T5: =集贸价格明细!M59 -> 5.2
A6: 46162 | B6: 5月第2周 | C6: =集贸价格明细!H76 -> 73.24 | D6: =集贸价格明细!H77 -> 67.73 | E6: =集贸价格明细!H78 -> 28.28 | F6: =集贸价格明细!H79 -> 72.53 | G6: =集贸价格明细!H80 -> 71.03 | H6: =集贸价格明细!H81 -> 30.84 | I6: =集贸价格明细!K76 -> 0.2 | J6: =集贸价格明细!M76 -> 4.9 | K6: =集贸价格明细!K77 -> 0.1 | L6: =集贸价格明细!M77 -> 0 | M6: =集贸价格明细!K78 -> 0.4 | N6: =集贸价格明细!M78 -> 4.9 | O6: =集贸价格明细!K79 -> -0.1 | P6: =集贸价格明细!M79 -> 4.4 | Q6: =集贸价格明细!K80 -> -0.1 | R6: =集贸价格明细!M80 -> 0 | S6: =集贸价格明细!K81 -> 0 | T6: =集贸价格明细!M81 -> 5
A7: 46156 | B7: 5月第1周 | C7: =集贸价格明细!H98 -> 73.09 | D7: =集贸价格明细!H99 -> 67.69 | E7: =集贸价格明细!H100 -> 28.16 | F7: =集贸价格明细!H101 -> 72.58 | G7: =集贸价格明细!H102 -> 71.07 | H7: =集贸价格明细!H103 -> 30.83 | I7: =集贸价格明细!K98 -> 0.4 | J7: =集贸价格明细!M98 -> 4.7 | K7: =集贸价格明细!K99 -> 0.6 | L7: =集贸价格明细!M99 -> 0 | M7: =集贸价格明细!K100 -> 0.9 | N7: =集贸价格明细!M100 -> 4.6 | O7: =集贸价格明细!K101 -> 0 | P7: =集贸价格明细!M101 -> 4.3 | Q7: =集贸价格明细!K102 -> 0.1 | R7: =集贸价格明细!M102 -> 0 | S7: =集贸价格明细!K103 -> 0.6 | T7: =集贸价格明细!M103 -> 4.8
A8: 46151 | B8: 4月第5周 | C8: =集贸价格明细!H120 -> 72.82 | D8: =集贸价格明细!H121 -> 67.28 | E8: =集贸价格明细!H122 -> 27.92 | F8: =集贸价格明细!H123 -> 72.56 | G8: =集贸价格明细!H124 -> 71.01 | H8: =集贸价格明细!H125 -> 30.66 | I8: =集贸价格明细!K120 -> 0.2 | J8: =集贸价格明细!M120 -> 4.7 | K8: =集贸价格明细!K121 -> 0.1 | L8: =集贸价格明细!M121 -> 0 | M8: =集贸价格明细!K122 -> 0.4 | N8: =集贸价格明细!M122 -> 3.6 | O8: =集贸价格明细!K123 -> 0 | P8: =集贸价格明细!M123 -> 4.2 | Q8: =集贸价格明细!K124 -> 0 | R8: =集贸价格明细!M124 -> 0 | S8: =集贸价格明细!K125 -> 0 | T8: =集贸价格明细!M125 -> 4.4
A9: 46151 | B9: 4月第4周 | C9: =集贸价格明细!H142 -> 72.67 | D9: =集贸价格明细!H143 -> 67.23 | E9: =集贸价格明细!H144 -> 27.82 | F9: =集贸价格明细!H145 -> 72.53 | G9: =集贸价格明细!H146 -> 71.01 | H9: =集贸价格明细!H147 -> 30.66 | I9: =集贸价格明细!K142 -> 0.3 | J9: =集贸价格明细!M142 -> 5.3 | K9: =集贸价格明细!K143 -> 0.4 | L9: =集贸价格明细!M143 -> 0 | M9: =集贸价格明细!K144 -> 0.6 | N9: =集贸价格明细!M144 -> 3.7 | O9: =集贸价格明细!K145 -> 0 | P9: =集贸价格明细!M145 -> 4.4 | Q9: =集贸价格明细!K146 -> 0 | R9: =集贸价格明细!M146 -> 0 | S9: =集贸价格明细!K147 -> 0 | T9: =集贸价格明细!M147 -> 4.8
A10: 46134 | B10: 4月第3周 | C10: =集贸价格明细!H164 -> 72.44 | D10: =集贸价格明细!H165 -> 66.93 | E10: =集贸价格明细!H166 -> 27.66 | F10: =集贸价格明细!H167 -> 72.56 | G10: =集贸价格明细!H168 -> 70.98 | H10: =集贸价格明细!H169 -> 30.67 | I10: =集贸价格明细!K164 -> 0.2 | J10: =集贸价格明细!M164 -> 5.7 | K10: =集贸价格明细!K165 -> 0.4 | L10: =集贸价格明细!M165 -> 0 | M10: =集贸价格明细!K166 -> 0.6 | N10: =集贸价格明细!M166 -> 4.2 | O10: =集贸价格明细!K167 -> 0 | P10: =集贸价格明细!M167 -> 4.6 | Q10: =集贸价格明细!K168 -> 0.3 | R10: =集贸价格明细!M168 -> 0 | S10: =集贸价格明细!K169 -> 0.4 | T10: =集贸价格明细!M169 -> 5.4
A11: 46127 | B11: 4月第2周 | C11: =集贸价格明细!H186 -> 72.29 | D11: =集贸价格明细!H187 -> 66.65 | E11: =集贸价格明细!H188 -> 27.49 | F11: =集贸价格明细!H189 -> 72.57 | G11: =集贸价格明细!H190 -> 70.78 | H11: =集贸价格明细!H191 -> 30.55 | I11: =集贸价格明细!K186 -> 0.3 | J11: =集贸价格明细!M186 -> 6.4 | K11: =集贸价格明细!K187 -> 0.4 | L11: =集贸价格明细!M187 -> 0 | M11: =集贸价格明细!K188 -> 0.7 | N11: =集贸价格明细!M188 -> 5.2 | O11: =集贸价格明细!K189 -> -0.1 | P11: =集贸价格明细!M189 -> 4.6 | Q11: =集贸价格明细!K190 -> 0.3 | R11: =集贸价格明细!M190 -> 0 | S11: =集贸价格明细!K191 -> 0.1 | T11: =集贸价格明细!M191 -> 5.3
A12: 46120 | B12: 4月第1周 | C12: =集贸价格明细!H208 -> 72.07 | D12: =集贸价格明细!H209 -> 66.36 | E12: =集贸价格明细!H210 -> 27.3 | F12: =集贸价格明细!H211 -> 72.61 | G12: =集贸价格明细!H212 -> 70.6 | H12: =集贸价格明细!H213 -> 30.53 | I12: =集贸价格明细!K208 -> 0.1 | J12: =集贸价格明细!M208 -> 7.2 | K12: =集贸价格明细!K209 -> 0.3 | L12: =集贸价格明细!M209 -> 0 | M12: =集贸价格明细!K210 -> 0.5 | N12: =集贸价格明细!M210 -> 6.1 | O12: =集贸价格明细!K211 -> -0.1 | P12: =集贸价格明细!M211 -> 4.7 | Q12: =集贸价格明细!K212 -> 0.1 | R12: =集贸价格明细!M212 -> 0 | S12: =集贸价格明细!K213 -> 0.2 | T12: =集贸价格明细!M213 -> 5.1
A13: 46111 | B13: 3月第4周 | C13: =集贸价格明细!H230 -> 72 | D13: =集贸价格明细!H231 -> 66.13 | E13: =集贸价格明细!H232 -> 27.17 | F13: =集贸价格明细!H233 -> 72.66 | G13: =集贸价格明细!H234 -> 70.54 | H13: =集贸价格明细!H235 -> 30.48 | I13: =集贸价格明细!K230 -> 0 | J13: =集贸价格明细!M230 -> 8.5 | K13: =集贸价格明细!K231 -> 0 | L13: =集贸价格明细!M231 -> 0 | M13: =集贸价格明细!K232 -> 0.3 | N13: =集贸价格明细!M232 -> 8.4 | O13: =集贸价格明细!K233 -> -0.3 | P13: =集贸价格明细!M233 -> 4.8 | Q13: =集贸价格明细!K234 -> -0.2 | R13: =集贸价格明细!M234 -> 0 | S13: =集贸价格明细!K235 -> -0.4 | T13: =集贸价格明细!M235 -> 5
A14: 46106 | B14: 3月第3周 | C14: =集贸价格明细!H252 -> 72 | D14: =集贸价格明细!H253 -> 66.12 | E14: =集贸价格明细!H254 -> 27.08 | F14: =集贸价格明细!H255 -> 72.85 | G14: =集贸价格明细!H256 -> 70.67 | H14: =集贸价格明细!H257 -> 30.61 | I14: =集贸价格明细!K252 -> -0.2 | J14: =集贸价格明细!M252 -> 9.7 | K14: =集贸价格明细!K253 -> 0.1 | L14: =集贸价格明细!M253 -> 0 | M14: =集贸价格明细!K254 -> 0.3 | N14: =集贸价格明细!M254 -> 12.5 | O14: =集贸价格明细!K255 -> -0.4 | P14: =集贸价格明细!M255 -> 5 | Q14: =集贸价格明细!K256 -> -0.4 | R14: =集贸价格明细!M256 -> 0 | S14: =集贸价格明细!K257 -> -0.5 | T14: =集贸价格明细!M257 -> 5.6
A15: 46099 | B15: 3月第2周 | C15: =集贸价格明细!H274 -> 72.16 | D15: =集贸价格明细!H275 -> 66.05 | E15: =集贸价格明细!H276 -> 27.01 | F15: =集贸价格明细!H277 -> 73.11 | G15: =集贸价格明细!H278 -> 70.94 | H15: =集贸价格明细!H279 -> 30.76 | I15: =集贸价格明细!K274 -> -0.3 | J15: =集贸价格明细!M274 -> 10.5 | K15: =集贸价格明细!K275 -> 0 | L15: =集贸价格明细!M275 -> 0 | M15: =集贸价格明细!K276 -> 0.3 | N15: =集贸价格明细!M276 -> 14.8 | O15: =集贸价格明细!K277 -> -0.6 | P15: =集贸价格明细!M277 -> 5.3 | Q15: =集贸价格明细!K278 -> -0.4 | R15: =集贸价格明细!M278 -> 0 | S15: =集贸价格明细!K279 -> 0 | T15: =集贸价格明细!M279 -> 6.5
A16: 46091 | B16: 3月第1周 | C16: =集贸价格明细!H296 -> 72.41 | D16: =集贸价格明细!H297 -> 66.06 | E16: =集贸价格明细!H298 -> 26.92 | F16: =集贸价格明细!H299 -> 73.56 | G16: =集贸价格明细!H300 -> 71.2 | H16: =集贸价格明细!H301 -> 30.88 | I16: =集贸价格明细!K296 -> -0.4 | J16: =集贸价格明细!M296 -> 11.1 | K16: =集贸价格明细!K297 -> -0.2 | L16: =集贸价格明细!M297 -> 0 | M16: =集贸价格明细!K298 -> -0.3 | N16: =集贸价格明细!M298 -> 16 | O16: =集贸价格明细!K299 -> -0.4 | P16: =集贸价格明细!M299 -> 5.8 | Q16: =集贸价格明细!K300 -> -0.4 | R16: =集贸价格明细!M300 -> 0 | S16: =集贸价格明细!K301 -> 0 | T16: =集贸价格明细!M301 -> 7.1
A17: 46084 | B17: 2月第4周 | C17: =集贸价格明细!H318 -> 72.69 | D17: =集贸价格明细!H319 -> 66.16 | E17: =集贸价格明细!H320 -> 26.99 | F17: =集贸价格明细!H321 -> 73.84 | G17: =集贸价格明细!H322 -> 71.49 | H17: =集贸价格明细!H323 -> 31.12 | I17: =集贸价格明细!K318 -> -0.2 | J17: =集贸价格明细!M318 -> 11.8 | K17: =集贸价格明细!K319 -> -0.2 | L17: =集贸价格明细!M319 -> 0 | M17: =集贸价格明细!K320 -> 0 | N17: =集贸价格明细!M320 -> 18.5 | O17: =集贸价格明细!K321 -> -0.2 | P17: =集贸价格明细!M321 -> 5.9 | Q17: =集贸价格明细!K322 -> -0.2 | R17: =集贸价格明细!M322 -> 0 | S17: =集贸价格明细!K323 -> 0 | T17: =集贸价格明细!M323 -> 8.3
A18: 46083 | B18: 2月第3周 | C18: =集贸价格明细!H340 -> 72.84 | D18: =集贸价格明细!H341 -> 66.26 | E18: =集贸价格明细!H342 -> 26.99 | F18: =集贸价格明细!H343 -> 73.99 | G18: =集贸价格明细!H344 -> 71.6 | H18: =集贸价格明细!H345 -> 31.17 | I18: =集贸价格明细!K340 -> 0.3 | J18: =集贸价格明细!M340 -> 11.8 | K18: =集贸价格明细!K341 -> -0.3 | L18: =集贸价格明细!M341 -> 0 | M18: =集贸价格明细!K342 -> -0.1 | N18: =集贸价格明细!M342 -> 19.6 | O18: =集贸价格明细!K343 -> 0.3 | P18: =集贸价格明细!M343 -> 5.8 | Q18: =集贸价格明细!K344 -> 0 | R18: =集贸价格明细!M344 -> 0 | S18: =集贸价格明细!K345 -> 0 | T18: =集贸价格明细!M345 -> 8.3
A19: 46079 | B19: 2月第2周 | C19: =集贸价格明细!H362 -> 72.65 | D19: =集贸价格明细!H363 -> 66.44 | E19: =集贸价格明细!H364 -> 27.02 | F19: =集贸价格明细!H365 -> 73.74 | G19: =集贸价格明细!H366 -> 71.6 | H19: =集贸价格明细!H367 -> 31.17 | I19: =集贸价格明细!K362 -> 0.5 | J19: =集贸价格明细!M362 -> 11 | K19: =集贸价格明细!K363 -> 0.3 | L19: =集贸价格明细!M363 -> 0 | M19: =集贸价格明细!K364 -> 0.1 | N19: =集贸价格明细!M364 -> 20.4 | O19: =集贸价格明细!K365 -> 0.8 | P19: =集贸价格明细!M365 -> 4.9 | Q19: =集贸价格明细!K366 -> 0.7 | R19: =集贸价格明细!M366 -> 0 | S19: =集贸价格明细!K367 -> 0.5 | T19: =集贸价格明细!M367 -> 8
A20: 46063 | B20: 2月第1周 | C20: =集贸价格明细!H384 -> 72.26 | D20: =集贸价格明细!H385 -> 66.22 | E20: =集贸价格明细!H386 -> 26.98 | F20: =集贸价格明细!H387 -> 73.17 | G20: =集贸价格明细!H388 -> 71.09 | H20: =集贸价格明细!H389 -> 31 | I20: =集贸价格明细!K384 -> 0.4 | J20: =集贸价格明细!M384 -> 10.1 | K20: =集贸价格明细!K385 -> 0.6 | L20: =集贸价格明细!M385 -> 0 | M20: =集贸价格明细!K386 -> 0.6 | N20: =集贸价格明细!M386 -> 21.3 | O20: =集贸价格明细!K387 -> 0.5 | P20: =集贸价格明细!M387 -> 3.7 | Q20: =集贸价格明细!K388 -> 0.7 | R20: =集贸价格明细!M388 -> 0 | S20: =集贸价格明细!K389 -> 0.7 | T20: =集贸价格明细!M389 -> 7
A21: 46057 | B21: 1月第5周 | C21: =集贸价格明细!H406 -> 71.99 | D21: =集贸价格明细!H407 -> 65.81 | E21: =集贸价格明细!H408 -> 26.82 | F21: =集贸价格明细!H409 -> 72.78 | G21: =集贸价格明细!H410 -> 70.58 | H21: =集贸价格明细!H411 -> 30.78 | I21: =集贸价格明细!K406 -> 0.3 | J21: =集贸价格明细!M406 -> 9.4 | K21: =集贸价格明细!K407 -> 0.2 | L21: =集贸价格明细!M407 -> 0 | M21: =集贸价格明细!K408 -> 0.4 | N21: =集贸价格明细!M408 -> 20.5 | O21: =集贸价格明细!K409 -> 0.5 | P21: =集贸价格明细!M409 -> 2.9 | Q21: =集贸价格明细!K410 -> 0.5 | R21: =集贸价格明细!M410 -> 0 | S21: =集贸价格明细!K411 -> 0.6 | T21: =集贸价格明细!M411 -> 5.9
A22: 46049 | B22: 1月第4周 | C22: =集贸价格明细!H428 -> 71.77 | D22: =集贸价格明细!H429 -> 65.66 | E22: =集贸价格明细!H430 -> 26.72 | F22: =集贸价格明细!H431 -> 72.43 | G22: =集贸价格明细!H432 -> 70.23 | H22: =集贸价格明细!H433 -> 30.61 | I22: =集贸价格明细!K428 -> 0.3 | J22: =集贸价格明细!M428 -> 9.7 | K22: =集贸价格明细!K429 -> 0.3 | L22: =集贸价格明细!M429 -> 0 | M22: =集贸价格明细!K430 -> 0.4 | N22: =集贸价格明细!M430 -> 20 | O22: =集贸价格明细!K431 -> 0.4 | P22: =集贸价格明细!M431 -> 3.1 | Q22: =集贸价格明细!K432 -> 0.4 | R22: =集贸价格明细!M432 -> 0 | S22: =集贸价格明细!K433 -> 0.4 | T22: =集贸价格明细!M433 -> 5.7
A23: 46045 | B23: 1月第3周 | C23: =集贸价格明细!H450 -> 71.57 | D23: =集贸价格明细!H451 -> 65.47 | E23: =集贸价格明细!H452 -> 26.61 | F23: =集贸价格明细!H453 -> 72.12 | G23: =集贸价格明细!H454 -> 69.92 | H23: =集贸价格明细!H455 -> 30.48 | I23: =集贸价格明细!K450 -> 0.2 | J23: =集贸价格明细!M450 -> 9.1 | K23: =集贸价格明细!K451 -> 0.3 | L23: =集贸价格明细!M451 -> 0 | M23: =集贸价格明细!K452 -> 0.2 | N23: =集贸价格明细!M452 -> 18.4 | O23: =集贸价格明细!K453 -> 0.3 | P23: =集贸价格明细!M453 -> 3.1 | Q23: =集贸价格明细!K454 -> 0.4 | R23: =集贸价格明细!M454 -> 0 | S23: =集贸价格明细!K455 -> 0.5 | T23: =集贸价格明细!M455 -> 5.3
A24: 46035 | B24: 1月第2周 | C24: =集贸价格明细!H472 -> 71.45 | D24: =集贸价格明细!H473 -> 65.28 | E24: =集贸价格明细!H474 -> 26.56 | F24: =集贸价格明细!H475 -> 71.94 | G24: =集贸价格明细!H476 -> 69.65 | H24: =集贸价格明细!H477 -> 30.34 | I24: =集贸价格明细!K472 -> 0.1 | J24: =集贸价格明细!M472 -> 8.7 | K24: =集贸价格明细!K473 -> 0 | L24: =集贸价格明细!M473 -> 0 | M24: =集贸价格明细!K474 -> 0.2 | N24: =集贸价格明细!M474 -> 17.6 | O24: =集贸价格明细!K475 -> 0.1 | P24: =集贸价格明细!M475 -> 3 | Q24: =集贸价格明细!K476 -> 0.1 | R24: =集贸价格明细!M476 -> 0 | S24: =集贸价格明细!K477 -> 0.3 | T24: =集贸价格明细!M477 -> 4.7
A25: 46027 | B25: 1月第1周 | C25: =集贸价格明细!H494 -> 71.4 | D25: =集贸价格明细!H495 -> 65.28 | E25: =集贸价格明细!H496 -> 26.52 | F25: =集贸价格明细!H497 -> 71.9 | G25: =集贸价格明细!H498 -> 69.61 | H25: =集贸价格明细!H499 -> 30.26 | I25: =集贸价格明细!K494 -> 0.1 | J25: =集贸价格明细!M494 -> 8.3 | K25: =集贸价格明细!K495 -> 0.2 | L25: =集贸价格明细!M495 -> 0 | M25: =集贸价格明细!K496 -> -0.1 | N25: =集贸价格明细!M496 -> 16.8 | O25: =集贸价格明细!K497 -> 0.2 | P25: =集贸价格明细!M497 -> 2.9 | Q25: =集贸价格明细!K498 -> 0.2 | R25: =集贸价格明细!M498 -> 0 | S25: =集贸价格明细!K499 -> 0.4 | T25: =集贸价格明细!M499 -> 4.3
A26: 46021 | B26: 12月第4周 | C26: =集贸价格明细!H516 -> 71.33 | D26: =集贸价格明细!H517 -> 65.18 | E26: =集贸价格明细!H518 -> 26.54 | F26: =集贸价格明细!H519 -> 71.74 | G26: =集贸价格明细!H520 -> 69.46 | H26: =集贸价格明细!H521 -> 30.14 | I26: =集贸价格明细!K516 -> 0 | J26: =集贸价格明细!M516 -> 7.9 | K26: =集贸价格明细!K517 -> 0.1 | L26: =集贸价格明细!M517 -> 0 | M26: =集贸价格明细!K518 -> 0.1 | N26: =集贸价格明细!M518 -> 16.2 | O26: =集贸价格明细!K519 -> 0.1 | P26: =集贸价格明细!M519 -> 2.6 | Q26: =集贸价格明细!K520 -> 0.1 | R26: =集贸价格明细!M520 -> 0 | S26: =集贸价格明细!K521 -> 0.1 | T26: =集贸价格明细!M521 -> 3.7
A27: 46014 | B27: 12月第3周 | C27: =集贸价格明细!H538 -> 71.3 | D27: =集贸价格明细!H539 -> 65.12 | E27: =集贸价格明细!H540 -> 26.52 | F27: =集贸价格明细!H541 -> 71.68 | G27: =集贸价格明细!H542 -> 69.39 | H27: =集贸价格明细!H543 -> 30.1 | I27: =集贸价格明细!K538 -> 0 | J27: =集贸价格明细!M538 -> 7.6 | K27: =集贸价格明细!K539 -> 0 | L27: =集贸价格明细!M539 -> 0 | M27: =集贸价格明细!K540 -> 0 | N27: =集贸价格明细!M540 -> 15.6 | O27: =集贸价格明细!K541 -> 0.1 | P27: =集贸价格明细!M541 -> 2.5 | Q27: =集贸价格明细!K542 -> 0.2 | R27: =集贸价格明细!M542 -> 0 | S27: =集贸价格明细!K543 -> 0 | T27: =集贸价格明细!M543 -> 3.6
A28: 46008 | B28: 12月第2周 | C28: =集贸价格明细!H560 -> 71.33 | D28: =集贸价格明细!H561 -> 65.14 | E28: =集贸价格明细!H562 -> 26.51 | F28: =集贸价格明细!H563 -> 71.59 | G28: =集贸价格明细!H564 -> 69.23 | H28: =集贸价格明细!H565 -> 30.09 | I28: =集贸价格明细!K560 -> 0 | J28: =集贸价格明细!M560 -> 7.3 | K28: =集贸价格明细!K561 -> -0.1 | L28: =集贸价格明细!M561 -> 0 | M28: =集贸价格明细!K562 -> -0.1 | N28: =集贸价格明细!M562 -> 15 | O28: =集贸价格明细!K563 -> 0.1 | P28: =集贸价格明细!M563 -> 2.4 | Q28: =集贸价格明细!K564 -> 0.1 | R28: =集贸价格明细!M564 -> 0 | S28: =集贸价格明细!K565 -> 0.3 | T28: =集贸价格明细!M565 -> 3.7
A29: 46000 | B29: 12月第1周 | C29: =集贸价格明细!H582 -> 71.32 | D29: =集贸价格明细!H583 -> 65.2 | E29: =集贸价格明细!H584 -> 26.53 | F29: =集贸价格明细!H585 -> 71.51 | G29: =集贸价格明细!H586 -> 69.13 | H29: =集贸价格明细!H587 -> 30.01 | I29: =集贸价格明细!K582 -> 0 | J29: =集贸价格明细!M582 -> 7.1 | K29: =集贸价格明细!K583 -> 0 | L29: =集贸价格明细!M583 -> 0 | M29: =集贸价格明细!K584 -> -0.3 | N29: =集贸价格明细!M584 -> 15 | O29: =集贸价格明细!K585 -> 0.2 | P29: =集贸价格明细!M585 -> 2.3 | Q29: =集贸价格明细!K586 -> 0.2 | R29: =集贸价格明细!M586 -> 0 | S29: =集贸价格明细!K587 -> 0.3 | T29: =集贸价格明细!M587 -> 3.5
A30: 45992 | B30: 11月第4周 | C30: =集贸价格明细!H604 -> 71.3 | D30: =集贸价格明细!H605 -> 65.2 | E30: =集贸价格明细!H606 -> 26.6 | F30: =集贸价格明细!H607 -> 71.37 | G30: =集贸价格明细!H608 -> 68.99 | H30: =集贸价格明细!H609 -> 29.91 | I30: =集贸价格明细!K604 -> -0.1 | J30: =集贸价格明细!M604 -> 6.8 | K30: =集贸价格明细!K605 -> 0 | L30: =集贸价格明细!M605 -> 0 | M30: =集贸价格明细!K606 -> -0.3 | N30: =集贸价格明细!M606 -> 14.8 | O30: =集贸价格明细!K607 -> 0.1 | P30: =集贸价格明细!M607 -> 1.9 | Q30: =集贸价格明细!K608 -> 0.2 | R30: =集贸价格明细!M608 -> 0 | S30: =集贸价格明细!K609 -> 0.2 | T30: =集贸价格明细!M609 -> 3.5
A31: 45985 | B31: 11月第3周 | C31: =集贸价格明细!H626 -> 71.37 | D31: =集贸价格明细!H627 -> 65.22 | E31: =集贸价格明细!H628 -> 26.68 | F31: =集贸价格明细!H629 -> 71.32 | G31: =集贸价格明细!H630 -> 68.88 | H31: =集贸价格明细!H631 -> 29.86 | I31: =集贸价格明细!K626 -> 0 | J31: =集贸价格明细!M626 -> 6.7 | K31: =集贸价格明细!K627 -> -0.2 | L31: =集贸价格明细!M627 -> 0 | M31: =集贸价格明细!K628 -> -0.3 | N31: =集贸价格明细!M628 -> 14.7 | O31: =集贸价格明细!K629 -> 0.3 | P31: =集贸价格明细!M629 -> 2 | Q31: =集贸价格明细!K630 -> 0.2 | R31: =集贸价格明细!M630 -> 0 | S31: =集贸价格明细!K631 -> 0.3 | T31: =集贸价格明细!M631 -> 3.6
A32: 45979 | B32: 11月第2周 | C32: =集贸价格明细!H648 -> 71.37 | D32: =集贸价格明细!H649 -> 65.33 | E32: =集贸价格明细!H650 -> 26.75 | F32: =集贸价格明细!H651 -> 71.11 | G32: =集贸价格明细!H652 -> 68.71 | H32: =集贸价格明细!H653 -> 29.78 | I32: =集贸价格明细!K648 -> -0.1 | J32: =集贸价格明细!M648 -> 6.6 | K32: =集贸价格明细!K649 -> -0.2 | L32: =集贸价格明细!M649 -> 0 | M32: =集贸价格明细!K650 -> -0.4 | N32: =集贸价格明细!M650 -> 14.4 | O32: =集贸价格明细!K651 -> 0.2 | P32: =集贸价格明细!M651 -> 1.8 | Q32: =集贸价格明细!K652 -> 0.3 | R32: =集贸价格明细!M652 -> 0 | S32: =集贸价格明细!K653 -> 0.3 | T32: =集贸价格明细!M653 -> 3.2
A33: 45972 | B33: 11月第1周 | C33: =集贸价格明细!H670 -> 71.46 | D33: =集贸价格明细!H671 -> 65.45 | E33: =集贸价格明细!H672 -> 26.86 | F33: =集贸价格明细!H673 -> 70.98 | G33: =集贸价格明细!H674 -> 68.52 | H33: =集贸价格明细!H675 -> 29.69 | I33: =集贸价格明细!K670 -> 0.2 | J33: =集贸价格明细!M670 -> 6.5 | K33: =集贸价格明细!K671 -> 0 | L33: =集贸价格明细!M671 -> 0 | M33: =集贸价格明细!K672 -> -0.3 | N33: =集贸价格明细!M672 -> 14.6 | O33: =集贸价格明细!K673 -> 0.3 | P33: =集贸价格明细!M673 -> 1.6 | Q33: =集贸价格明细!K674 -> 0.2 | R33: =集贸价格明细!M674 -> 0 | S33: =集贸价格明细!K675 -> 0.5 | T33: =集贸价格明细!M675 -> 2.9
A34: 45965 | B34: 10月第4周 | C34: =集贸价格明细!H692 -> 71.32 | D34: =集贸价格明细!H693 -> 65.45 | E34: =集贸价格明细!H694 -> 26.94 | F34: =集贸价格明细!H695 -> 70.78 | G34: =集贸价格明细!H696 -> 68.38 | H34: =集贸价格明细!H697 -> 29.55 | I34: =集贸价格明细!K692 -> 0.1 | J34: =集贸价格明细!M692 -> 6.1 | K34: =集贸价格明细!K693 -> 0.1 | L34: =集贸价格明细!M693 -> 0 | M34: =集贸价格明细!K694 -> -0.3 | N34: =集贸价格明细!M694 -> 14.8 | O34: =集贸价格明细!K695 -> 0.2 | P34: =集贸价格明细!M695 -> 1.2 | Q34: =集贸价格明细!K696 -> 0.3 | R34: =集贸价格明细!M696 -> 0 | S34: =集贸价格明细!K697 -> 0.2 | T34: =集贸价格明细!M697 -> 2.7
A35: 45959 | B35: 10月第3周 | C35: =集贸价格明细!H714 -> 71.27 | D35: =集贸价格明细!H715 -> 65.36 | E35: =集贸价格明细!H716 -> 27.01 | F35: =集贸价格明细!H717 -> 70.61 | G35: =集贸价格明细!H718 -> 68.16 | H35: =集贸价格明细!H719 -> 29.49 | I35: =集贸价格明细!K714 -> 0 | J35: =集贸价格明细!M714 -> 5.8 | K35: =集贸价格明细!K715 -> 0.1 | L35: =集贸价格明细!M715 -> 0 | M35: =集贸价格明细!K716 -> -0.3 | N35: =集贸价格明细!M716 -> 14.4 | O35: =集贸价格明细!K717 -> 0.2 | P35: =集贸价格明细!M717 -> 1 | Q35: =集贸价格明细!K718 -> 0.2 | R35: =集贸价格明细!M718 -> 0 | S35: =集贸价格明细!K719 -> 0.1 | T35: =集贸价格明细!M719 -> 2.6
A36: 45950 | B36: 10月第2周 | C36: =集贸价格明细!H736 -> 71.3 | D36: =集贸价格明细!H737 -> 65.3 | E36: =集贸价格明细!H738 -> 27.08 | F36: =集贸价格明细!H739 -> 70.47 | G36: =集贸价格明细!H740 -> 68.05 | H36: =集贸价格明细!H741 -> 29.45 | I36: =集贸价格明细!K736 -> 0 | J36: =集贸价格明细!M736 -> 5.6 | K36: =集贸价格明细!K737 -> -0.1 | L36: =集贸价格明细!M737 -> 0 | M36: =集贸价格明细!K738 -> -0.1 | N36: =集贸价格明细!M738 -> 14.3 | O36: =集贸价格明细!K739 -> -0.1 | P36: =集贸价格明细!M739 -> 0.7 | Q36: =集贸价格明细!K740 -> 0 | R36: =集贸价格明细!M740 -> 0 | S36: =集贸价格明细!K741 -> 0 | T36: =集贸价格明细!M741 -> 2.5
A37: 45943 | B37: 10月第1周 | C37: =集贸价格明细!H758 -> 71.33 | D37: =集贸价格明细!H759 -> 65.37 | E37: =集贸价格明细!H760 -> 27.11 | F37: =集贸价格明细!H761 -> 70.52 | G37: =集贸价格明细!H762 -> 68.07 | H37: =集贸价格明细!H763 -> 29.44 | I37: =集贸价格明细!K758 -> 0.1 | J37: =集贸价格明细!M758 -> 5.2 | K37: =集贸价格明细!K759 -> -0.1 | L37: =集贸价格明细!M759 -> 0 | M37: =集贸价格明细!K760 -> -0.2 | N37: =集贸价格明细!M760 -> 13.6 | O37: =集贸价格明细!K761 -> 0.6 | P37: =集贸价格明细!M761 -> 0.5 | Q37: =集贸价格明细!K762 -> 0.2 | R37: =集贸价格明细!M762 -> 0 | S37: =集贸价格明细!K763 -> 0.4 | T37: =集贸价格明细!M763 -> 2.6
A38: 45941 | B38: 9月第5周 | C38: =集贸价格明细!H780 -> 71.26 | D38: =集贸价格明细!H781 -> 65.46 | E38: =集贸价格明细!H782 -> 27.16 | F38: =集贸价格明细!H783 -> 70.13 | G38: =集贸价格明细!H784 -> 67.92 | H38: =集贸价格明细!H785 -> 29.33 | I38: =集贸价格明细!K780 -> 0.2 | J38: =集贸价格明细!M780 -> 5 | K38: =集贸价格明细!K781 -> 0.2 | L38: =集贸价格明细!M781 -> 0 | M38: =集贸价格明细!K782 -> 0.1 | N38: =集贸价格明细!M782 -> 13.6 | O38: =集贸价格明细!K783 -> 0.5 | P38: =集贸价格明细!M783 -> -0.1 | Q38: =集贸价格明细!K784 -> 0.5 | R38: =集贸价格明细!M784 -> 0 | S38: =集贸价格明细!K785 -> 0.4 | T38: =集贸价格明细!M785 -> 2.2
A39: 45929 | B39: 9月第4周 | C39: =集贸价格明细!H802 -> 71.11 | D39: =集贸价格明细!H803 -> 65.32 | E39: =集贸价格明细!H804 -> 27.14 | F39: =集贸价格明细!H805 -> 69.79 | G39: =集贸价格明细!H806 -> 67.58 | H39: =集贸价格明细!H807 -> 29.2 | I39: =集贸价格明细!K802 -> 0.3 | J39: =集贸价格明细!M802 -> 4.6 | K39: =集贸价格明细!K803 -> 0.3 | L39: =集贸价格明细!M803 -> 0 | M39: =集贸价格明细!K804 -> 0 | N39: =集贸价格明细!M804 -> 12.5 | O39: =集贸价格明细!K805 -> 0.4 | P39: =集贸价格明细!M805 -> -0.6 | Q39: =集贸价格明细!K806 -> 0.5 | R39: =集贸价格明细!M806 -> 0 | S39: =集贸价格明细!K807 -> 0.6 | T39: =集贸价格明细!M807 -> 1.5
A40: 45922 | B40: 9月第3周 | C40: =集贸价格明细!H824 -> 70.91 | D40: =集贸价格明细!H825 -> 65.1 | E40: =集贸价格明细!H826 -> 27.14 | F40: =集贸价格明细!H827 -> 69.53 | G40: =集贸价格明细!H828 -> 67.22 | H40: =集贸价格明细!H829 -> 29.04 | I40: =集贸价格明细!K824 -> 0.3 | J40: =集贸价格明细!M824 -> 3.8 | K40: =集贸价格明细!K825 -> 0.3 | L40: =集贸价格明细!M825 -> 0 | M40: =集贸价格明细!K826 -> -0.1 | N40: =集贸价格明细!M826 -> 11.3 | O40: =集贸价格明细!K827 -> 0.3 | P40: =集贸价格明细!M827 -> -1.2 | Q40: =集贸价格明细!K828 -> 0.4 | R40: =集贸价格明细!M828 -> 0 | S40: =集贸价格明细!K829 -> 0.3 | T40: =集贸价格明细!M829 -> 0.6
...

Sheet 生鲜乳价格
C1: 指标价格
A2: 时间 | B2: 周期 | C2: 生鲜乳(主产省份)价格（元/kg） | D2: 生鲜乳(主产省份)环比 | E2: 生鲜乳(主产省份)同比
A3: 46183 | B3: 6月第1周 | C3: =集贸价格明细!H16 -> 3.03 | D3: =集贸价格明细!K16 -> 0 | E3: =集贸价格明细!M16 -> -0.7
A4: 46176 | B4: 5月第4周 | C4: =集贸价格明细!H38 -> 3.03 | D4: =集贸价格明细!K38 -> 0 | E4: =集贸价格明细!M38 -> -1
A5: 46168 | B5: 5月第3周 | C5: =集贸价格明细!H60 -> 3.03 | D5: =集贸价格明细!K60 -> 0.3 | E5: =集贸价格明细!M60 -> -1.3
A6: 46162 | B6: 5月第2周 | C6: =集贸价格明细!H82 -> 3.02 | D6: =集贸价格明细!K82 -> 0 | E6: =集贸价格明细!M82 -> -1.6
A7: 46156 | B7: 5月第1周 | C7: =集贸价格明细!H104 -> 3.02 | D7: =集贸价格明细!K104 -> 0 | E7: =集贸价格明细!M104 -> -1.6
A8: 46151 | B8: 4月第5周 | C8: =集贸价格明细!H126 -> 3.02 | D8: =集贸价格明细!K126 -> 0 | E8: =集贸价格明细!M126 -> -1.9
A9: 46151 | B9: 4月第4周 | C9: =集贸价格明细!H148 -> 3.02 | D9: =集贸价格明细!K148 -> 0.3 | E9: =集贸价格明细!M148 -> -1.6
A10: 46134 | B10: 4月第3周 | C10: =集贸价格明细!H170 -> 3.01 | D10: =集贸价格明细!K170 -> -0.3 | E10: =集贸价格明细!M170 -> -2.3
A11: 46127 | B11: 4月第2周 | C11: =集贸价格明细!H192 -> 3.02 | D11: =集贸价格明细!K192 -> 0 | E11: =集贸价格明细!M192 -> -1.6
A12: 46120 | B12: 4月第1周 | C12: =集贸价格明细!H214 -> 3.02 | D12: =集贸价格明细!K214 -> 0 | E12: =集贸价格明细!M214 -> -1.6
A13: 46111 | B13: 3月第4周 | C13: =集贸价格明细!H236 -> 3.02 | D13: =集贸价格明细!K236 -> -0.3 | E13: =集贸价格明细!M236 -> -1.9
A14: 46106 | B14: 3月第3周 | C14: =集贸价格明细!H258 -> 3.03 | D14: =集贸价格明细!K258 -> 0.3 | E14: =集贸价格明细!M258 -> -1.9
A15: 46099 | B15: 3月第2周 | C15: =集贸价格明细!H280 -> 3.02 | D15: =集贸价格明细!K280 -> -0.3 | E15: =集贸价格明细!M280 -> -1.9
A16: 46091 | B16: 3月第1周 | C16: =集贸价格明细!H302 -> 3.03 | D16: =集贸价格明细!K302 -> 0 | E16: =集贸价格明细!M302 -> -1.6
A17: 46084 | B17: 2月第4周 | C17: =集贸价格明细!H324 -> 3.03 | D17: =集贸价格明细!K324 -> 0 | E17: =集贸价格明细!M324 -> -1.9
A18: 46083 | B18: 2月第3周 | C18: =集贸价格明细!H346 -> 3.03 | D18: =集贸价格明细!K346 -> -0.3 | E18: =集贸价格明细!M346 -> -2.3
A19: 46079 | B19: 2月第2周 | C19: =集贸价格明细!H368 -> 3.04 | D19: =集贸价格明细!K368 -> 0 | E19: =集贸价格明细!M368 -> -2.3
A20: 46063 | B20: 2月第1周 | C20: =集贸价格明细!H390 -> 3.04 | D20: =集贸价格明细!K390 -> 0 | E20: =集贸价格明细!M390 -> -2.6
A21: 46057 | B21: 1月第5周 | C21: =集贸价格明细!H412 -> 3.04 | D21: =集贸价格明细!K412 -> 0 | E21: =集贸价格明细!M412 -> -2.9
A22: 46049 | B22: 1月第4周 | C22: =集贸价格明细!H434 -> 3.04 | D22: =集贸价格明细!K434 -> 0.3 | E22: =集贸价格明细!M434 -> -2.6
A23: 46045 | B23: 1月第3周 | C23: =集贸价格明细!H456 -> 3.03 | D23: =集贸价格明细!K456 -> 0.3 | E23: =集贸价格明细!M456 -> -2.6
A24: 46035 | B24: 1月第2周 | C24: =集贸价格明细!H478 -> 3.02 | D24: =集贸价格明细!K478 -> -0.3 | E24: =集贸价格明细!M478 -> -3.2
A25: 46027 | B25: 1月第1周 | C25: =集贸价格明细!H500 -> 3.03 | D25: =集贸价格明细!K500 -> 0 | E25: =集贸价格明细!M500 -> -2.9
A26: 46021 | B26: 12月第4周 | C26: =集贸价格明细!H522 -> 3.03 | D26: =集贸价格明细!K522 -> 0 | E26: =集贸价格明细!M522 -> -2.6
A27: 46014 | B27: 12月第3周 | C27: =集贸价格明细!H544 -> 3.03 | D27: =集贸价格明细!K544 -> 0.3 | E27: =集贸价格明细!M544 -> -2.6
A28: 46008 | B28: 12月第2周 | C28: =集贸价格明细!H566 -> 3.02 | D28: =集贸价格明细!K566 -> 0 | E28: =集贸价格明细!M566 -> -2.9
A29: 46000 | B29: 12月第1周 | C29: =集贸价格明细!H588 -> 3.02 | D29: =集贸价格明细!K588 -> 0 | E29: =集贸价格明细!M588 -> -3.2
A30: 45992 | B30: 11月第4周 | C30: =集贸价格明细!H610 -> 3.02 | D30: =集贸价格明细!K610 -> -0.3 | E30: =集贸价格明细!M610 -> -3.2
A31: 45985 | B31: 11月第3周 | C31: =集贸价格明细!H632 -> 3.03 | D31: =集贸价格明细!K632 -> 0 | E31: =集贸价格明细!M632 -> -3.2
A32: 45979 | B32: 11月第2周 | C32: =集贸价格明细!H654 -> 3.03 | D32: =集贸价格明细!K654 -> 0.3 | E32: =集贸价格明细!M654 -> -2.9
A33: 45972 | B33: 11月第1周 | C33: =集贸价格明细!H676 -> 3.02 | D33: =集贸价格明细!K676 -> -0.3 | E33: =集贸价格明细!M676 -> -3.2
A34: 45965 | B34: 10月第4周 | C34: =集贸价格明细!H698 -> 3.03 | D34: =集贸价格明细!K698 -> -0.3 | E34: =集贸价格明细!M698 -> -3.2
A35: 45959 | B35: 10月第3周 | C35: =集贸价格明细!H720 -> 3.04 | D35: =集贸价格明细!K720 -> 0 | E35: =集贸价格明细!M720 -> -2.9
A36: 45950 | B36: 10月第2周 | C36: =集贸价格明细!H742 -> 3.04 | D36: =集贸价格明细!K742 -> 0 | E36: =集贸价格明细!M742 -> -2.9
A37: 45943 | B37: 10月第1周 | C37: =集贸价格明细!H764 -> 3.04 | D37: =集贸价格明细!K764 -> 0 | E37: =集贸价格明细!M764 -> -2.9
A38: 45941 | B38: 9月第5周 | C38: =集贸价格明细!H786 -> 3.04 | D38: =集贸价格明细!K786 -> 0 | E38: =集贸价格明细!M786 -> -3.2
A39: 45929 | B39: 9月第4周 | C39: =集贸价格明细!H808 -> 3.04 | D39: =集贸价格明细!K808 -> 0.3 | E39: =集贸价格明细!M808 -> -3.2
A40: 45922 | B40: 9月第3周 | C40: =集贸价格明细!H830 -> 3.03 | D40: =集贸价格明细!K830 -> 0 | E40: =集贸价格明细!M830 -> -3.5
...

Sheet 饲料价格
C1: 指标价格
A2: 时间 | B2: 周期 | C2: 玉米价格（元/kg） | D2: 玉米(东北三省)价格（元/kg） | E2: 玉米(广东省)价格（元/kg） | F2: 豆粕价格（元/kg） | G2: 育肥猪配合饲料价格（元/kg） | H2: 肉鸡配合饲料价格（元/kg） | I2: 蛋鸡配合饲料价格（元/kg） | J2: 玉米环比 | K2: 玉米同比 | L2: 玉米(东北三省)环比 | M2: 玉米(东北三省)同比 | N2: 玉米(广东省)环比 | O2: 玉米(广东省)同比 | P2: 豆粕环比 | Q2: 豆粕同比 | R2: 育肥猪配合饲料环比 | S2: 育肥猪配合饲料同比 | T2: 肉鸡配合饲料环比 | U2: 肉鸡配合饲料同比 | V2: 蛋鸡配合饲料环比 | W2: 蛋鸡配合饲料同比
A3: 46183 | B3: 6月第1周 | C3: =集贸价格明细!H17 -> 2.49 | D3: =集贸价格明细!H18 -> 2.34 | E3: =集贸价格明细!H19 -> 2.54 | F3: =集贸价格明细!H20 -> 3.24 | G3: =集贸价格明细!H21 -> 3.39 | H3: =集贸价格明细!H22 -> 3.52 | I3: =集贸价格明细!H23 -> 3.25 | J3: =集贸价格明细!K17 -> -0.4 | K3: =集贸价格明细!M17 -> 1.2 | L3: =集贸价格明细!K18 -> 0 | M3: =集贸价格明细!M18 -> 0 | N3: =集贸价格明细!K19 -> 0 | O3: =集贸价格明细!M19 -> 0 | P3: =集贸价格明细!K20 -> -0.6 | Q3: =集贸价格明细!M20 -> -4.7 | R3: =集贸价格明细!K21 -> 0 | S3: =集贸价格明细!M21 -> -0.3 | T3: =集贸价格明细!K22 -> 0 | U3: =集贸价格明细!M22 -> -0.3 | V3: =集贸价格明细!K23 -> 0 | W3: =集贸价格明细!M23 -> 0
A4: 46176 | B4: 5月第4周 | C4: =集贸价格明细!H39 -> 2.5 | D4: =集贸价格明细!H40 -> 2.34 | E4: =集贸价格明细!H41 -> 2.54 | F4: =集贸价格明细!H42 -> 3.26 | G4: =集贸价格明细!H43 -> 3.39 | H4: =集贸价格明细!H44 -> 3.52 | I4: =集贸价格明细!H45 -> 3.25 | J4: =集贸价格明细!K39 -> 0 | K4: =集贸价格明细!M39 -> 2 | L4: =集贸价格明细!K40 -> 0 | M4: =集贸价格明细!M40 -> 0 | N4: =集贸价格明细!K41 -> 0 | O4: =集贸价格明细!M41 -> 0 | P4: =集贸价格明细!K42 -> -0.6 | Q4: =集贸价格明细!M42 -> -5.8 | R4: =集贸价格明细!K43 -> 0 | S4: =集贸价格明细!M43 -> -0.6 | T4: =集贸价格明细!K44 -> -0.3 | U4: =集贸价格明细!M44 -> -0.3 | V4: =集贸价格明细!K45 -> 0 | W4: =集贸价格明细!M45 -> 0
A5: 46168 | B5: 5月第3周 | C5: =集贸价格明细!H61 -> 2.5 | D5: =集贸价格明细!H62 -> 2.34 | E5: =集贸价格明细!H63 -> 2.54 | F5: =集贸价格明细!H64 -> 3.28 | G5: =集贸价格明细!H65 -> 3.39 | H5: =集贸价格明细!H66 -> 3.53 | I5: =集贸价格明细!H67 -> 3.25 | J5: =集贸价格明细!K61 -> 0 | K5: =集贸价格明细!M61 -> 2 | L5: =集贸价格明细!K62 -> 0 | M5: =集贸价格明细!M62 -> 0 | N5: =集贸价格明细!K63 -> 0 | O5: =集贸价格明细!M63 -> 0 | P5: =集贸价格明细!K64 -> -0.3 | Q5: =集贸价格明细!M64 -> -6.6 | R5: =集贸价格明细!K65 -> -0.3 | S5: =集贸价格明细!M65 -> -0.9 | T5: =集贸价格明细!K66 -> 0 | U5: =集贸价格明细!M66 -> 0 | V5: =集贸价格明细!K67 -> 0 | W5: =集贸价格明细!M67 -> 0
A6: 46162 | B6: 5月第2周 | C6: =集贸价格明细!H83 -> 2.5 | D6: =集贸价格明细!H84 -> 2.34 | E6: =集贸价格明细!H85 -> 2.54 | F6: =集贸价格明细!H86 -> 3.29 | G6: =集贸价格明细!H87 -> 3.4 | H6: =集贸价格明细!H88 -> 3.53 | I6: =集贸价格明细!H89 -> 3.25 | J6: =集贸价格明细!K83 -> 0 | K6: =集贸价格明细!M83 -> 2.9 | L6: =集贸价格明细!K84 -> 0 | M6: =集贸价格明细!M84 -> 0 | N6: =集贸价格明细!K85 -> -0.4 | O6: =集贸价格明细!M85 -> 0 | P6: =集贸价格明细!K86 -> -0.3 | Q6: =集贸价格明细!M86 -> -8.9 | R6: =集贸价格明细!K87 -> 0 | S6: =集贸价格明细!M87 -> -0.9 | T6: =集贸价格明细!K88 -> 0 | U6: =集贸价格明细!M88 -> -0.3 | V6: =集贸价格明细!K89 -> -0.3 | W6: =集贸价格明细!M89 -> -0.3
A7: 46156 | B7: 5月第1周 | C7: =集贸价格明细!H105 -> 2.5 | D7: =集贸价格明细!H106 -> 2.34 | E7: =集贸价格明细!H107 -> 2.55 | F7: =集贸价格明细!H108 -> 3.3 | G7: =集贸价格明细!H109 -> 3.4 | H7: =集贸价格明细!H110 -> 3.53 | I7: =集贸价格明细!H111 -> 3.26 | J7: =集贸价格明细!K105 -> 0 | K7: =集贸价格明细!M105 -> 3.3 | L7: =集贸价格明细!K106 -> 0 | M7: =集贸价格明细!M106 -> 0 | N7: =集贸价格明细!K107 -> 0 | O7: =集贸价格明细!M107 -> 0 | P7: =集贸价格明细!K108 -> -0.3 | Q7: =集贸价格明细!M108 -> -10.6 | R7: =集贸价格明细!K109 -> 0 | S7: =集贸价格明细!M109 -> -0.9 | T7: =集贸价格明细!K110 -> 0 | U7: =集贸价格明细!M110 -> -0.3 | V7: =集贸价格明细!K111 -> 0 | W7: =集贸价格明细!M111 -> -0.3
A8: 46151 | B8: 4月第5周 | C8: =集贸价格明细!H127 -> 2.5 | D8: =集贸价格明细!H128 -> 2.34 | E8: =集贸价格明细!H129 -> 2.55 | F8: =集贸价格明细!H130 -> 3.31 | G8: =集贸价格明细!H131 -> 3.4 | H8: =集贸价格明细!H132 -> 3.53 | I8: =集贸价格明细!H133 -> 3.26 | J8: =集贸价格明细!K127 -> 0 | K8: =集贸价格明细!M127 -> 4.2 | L8: =集贸价格明细!K128 -> 0 | M8: =集贸价格明细!M128 -> 0 | N8: =集贸价格明细!K129 -> -0.4 | O8: =集贸价格明细!M129 -> 0 | P8: =集贸价格明细!K130 -> -0.9 | Q8: =集贸价格明细!M130 -> -12.2 | R8: =集贸价格明细!K131 -> -0.3 | S8: =集贸价格明细!M131 -> -0.9 | T8: =集贸价格明细!K132 -> 0 | U8: =集贸价格明细!M132 -> -0.6 | V8: =集贸价格明细!K133 -> 0 | W8: =集贸价格明细!M133 -> -0.3
A9: 46151 | B9: 4月第4周 | C9: =集贸价格明细!H149 -> 2.5 | D9: =集贸价格明细!H150 -> 2.34 | E9: =集贸价格明细!H151 -> 2.56 | F9: =集贸价格明细!H152 -> 3.34 | G9: =集贸价格明细!H153 -> 3.41 | H9: =集贸价格明细!H154 -> 3.53 | I9: =集贸价格明细!H155 -> 3.26 | J9: =集贸价格明细!K149 -> 0 | K9: =集贸价格明细!M149 -> 5 | L9: =集贸价格明细!K150 -> 0 | M9: =集贸价格明细!M150 -> 0 | N9: =集贸价格明细!K151 -> 0 | O9: =集贸价格明细!M151 -> 0 | P9: =集贸价格明细!K152 -> -0.9 | Q9: =集贸价格明细!M152 -> -9.7 | R9: =集贸价格明细!K153 -> 0 | S9: =集贸价格明细!M153 -> 0 | T9: =集贸价格明细!K154 -> -0.3 | U9: =集贸价格明细!M154 -> 0 | V9: =集贸价格明细!K155 -> 0 | W9: =集贸价格明细!M155 -> 0
A10: 46134 | B10: 4月第3周 | C10: =集贸价格明细!H171 -> 2.5 | D10: =集贸价格明细!H172 -> 2.34 | E10: =集贸价格明细!H173 -> 2.56 | F10: =集贸价格明细!H174 -> 3.37 | G10: =集贸价格明细!H175 -> 3.41 | H10: =集贸价格明细!H176 -> 3.54 | I10: =集贸价格明细!H177 -> 3.26 | J10: =集贸价格明细!K171 -> 0 | K10: =集贸价格明细!M171 -> 5 | L10: =集贸价格明细!K172 -> 0 | M10: =集贸价格明细!M172 -> 0 | N10: =集贸价格明细!K173 -> -0.4 | O10: =集贸价格明细!M173 -> 0 | P10: =集贸价格明细!K174 -> -1.2 | Q10: =集贸价格明细!M174 -> -6.6 | R10: =集贸价格明细!K175 -> 0 | S10: =集贸价格明细!M175 -> 0.3 | T10: =集贸价格明细!K176 -> 0 | U10: =集贸价格明细!M176 -> 0.6 | V10: =集贸价格明细!K177 -> 0 | W10: =集贸价格明细!M177 -> 0.3
A11: 46127 | B11: 4月第2周 | C11: =集贸价格明细!H193 -> 2.5 | D11: =集贸价格明细!H194 -> 2.34 | E11: =集贸价格明细!H195 -> 2.57 | F11: =集贸价格明细!H196 -> 3.41 | G11: =集贸价格明细!H197 -> 3.41 | H11: =集贸价格明细!H198 -> 3.54 | I11: =集贸价格明细!H199 -> 3.26 | J11: =集贸价格明细!K193 -> 0 | K11: =集贸价格明细!M193 -> 5.5 | L11: =集贸价格明细!K194 -> 0.4 | M11: =集贸价格明细!M194 -> 0 | N11: =集贸价格明细!K195 -> 0 | O11: =集贸价格明细!M195 -> 0 | P11: =集贸价格明细!K196 -> -0.9 | Q11: =集贸价格明细!M196 -> -3.9 | R11: =集贸价格明细!K197 -> 0 | S11: =集贸价格明细!M197 -> 0.3 | T11: =集贸价格明细!K198 -> 0 | U11: =集贸价格明细!M198 -> 0.6 | V11: =集贸价格明细!K199 -> -0.3 | W11: =集贸价格明细!M199 -> 0.3
A12: 46120 | B12: 4月第1周 | C12: =集贸价格明细!H215 -> 2.5 | D12: =集贸价格明细!H216 -> 2.33 | E12: =集贸价格明细!H217 -> 2.57 | F12: =集贸价格明细!H218 -> 3.44 | G12: =集贸价格明细!H219 -> 3.41 | H12: =集贸价格明细!H220 -> 3.54 | I12: =集贸价格明细!H221 -> 3.27 | J12: =集贸价格明细!K215 -> 0 | K12: =集贸价格明细!M215 -> 5.9 | L12: =集贸价格明细!K216 -> 0 | M12: =集贸价格明细!M216 -> 0 | N12: =集贸价格明细!K217 -> 0.4 | O12: =集贸价格明细!M217 -> 0 | P12: =集贸价格明细!K218 -> -0.6 | Q12: =集贸价格明细!M218 -> -2.8 | R12: =集贸价格明细!K219 -> 0 | S12: =集贸价格明细!M219 -> 0.3 | T12: =集贸价格明细!K220 -> 0.3 | U12: =集贸价格明细!M220 -> 0.6 | V12: =集贸价格明细!K221 -> 0.3 | W12: =集贸价格明细!M221 -> 0.9
A13: 46111 | B13: 3月第4周 | C13: =集贸价格明细!H237 -> 2.5 | D13: =集贸价格明细!H238 -> 2.33 | E13: =集贸价格明细!H239 -> 2.56 | F13: =集贸价格明细!H240 -> 3.46 | G13: =集贸价格明细!H241 -> 3.41 | H13: =集贸价格明细!H242 -> 3.53 | I13: =集贸价格明细!H243 -> 3.26 | J13: =集贸价格明细!K237 -> 0.4 | K13: =集贸价格明细!M237 -> 5.9 | L13: =集贸价格明细!K238 -> 0.4 | M13: =集贸价格明细!M238 -> 0 | N13: =集贸价格明细!K239 -> 0 | O13: =集贸价格明细!M239 -> 0 | P13: =集贸价格明细!K240 -> 0.6 | Q13: =集贸价格明细!M240 -> -3.9 | R13: =集贸价格明细!K241 -> 0.3 | S13: =集贸价格明细!M241 -> 0 | T13: =集贸价格明细!K242 -> 0 | U13: =集贸价格明细!M242 -> 0 | V13: =集贸价格明细!K243 -> 0 | W13: =集贸价格明细!M243 -> 0.6
A14: 46106 | B14: 3月第3周 | C14: =集贸价格明细!H259 -> 2.49 | D14: =集贸价格明细!H260 -> 2.32 | E14: =集贸价格明细!H261 -> 2.56 | F14: =集贸价格明细!H262 -> 3.44 | G14: =集贸价格明细!H263 -> 3.4 | H14: =集贸价格明细!H264 -> 3.53 | I14: =集贸价格明细!H265 -> 3.26 | J14: =集贸价格明细!K259 -> 0.8 | K14: =集贸价格明细!M259 -> 6 | L14: =集贸价格明细!K260 -> 0.4 | M14: =集贸价格明细!M260 -> 0 | N14: =集贸价格明细!K261 -> 1.2 | O14: =集贸价格明细!M261 -> 0 | P14: =集贸价格明细!K262 -> 1.8 | Q14: =集贸价格明细!M262 -> -6.8 | R14: =集贸价格明细!K263 -> 0.3 | S14: =集贸价格明细!M263 -> -0.6 | T14: =集贸价格明细!K264 -> 0.3 | U14: =集贸价格明细!M264 -> -0.6 | V14: =集贸价格明细!K265 -> 0.6 | W14: =集贸价格明细!M265 -> 0.3
A15: 46099 | B15: 3月第2周 | C15: =集贸价格明细!H281 -> 2.47 | D15: =集贸价格明细!H282 -> 2.31 | E15: =集贸价格明细!H283 -> 2.53 | F15: =集贸价格明细!H284 -> 3.38 | G15: =集贸价格明细!H285 -> 3.39 | H15: =集贸价格明细!H286 -> 3.52 | I15: =集贸价格明细!H287 -> 3.24 | J15: =集贸价格明细!K281 -> 0.8 | K15: =集贸价格明细!M281 -> 5.6 | L15: =集贸价格明细!K282 -> 1.3 | M15: =集贸价格明细!M282 -> 0 | N15: =集贸价格明细!K283 -> 0.8 | O15: =集贸价格明细!M283 -> 0 | P15: =集贸价格明细!K284 -> 1.8 | Q15: =集贸价格明细!M284 -> -9.6 | R15: =集贸价格明细!K285 -> 0.3 | S15: =集贸价格明细!M285 -> -1.2 | T15: =集贸价格明细!K286 -> 0.3 | U15: =集贸价格明细!M286 -> -0.8 | V15: =集贸价格明细!K287 -> 0.3 | W15: =集贸价格明细!M287 -> -0.3
A16: 46091 | B16: 3月第1周 | C16: =集贸价格明细!H303 -> 2.45 | D16: =集贸价格明细!H304 -> 2.28 | E16: =集贸价格明细!H305 -> 2.51 | F16: =集贸价格明细!H306 -> 3.32 | G16: =集贸价格明细!H307 -> 3.38 | H16: =集贸价格明细!H308 -> 3.51 | I16: =集贸价格明细!H309 -> 3.23 | J16: =集贸价格明细!K303 -> 0 | K16: =集贸价格明细!M303 -> 5.2 | L16: =集贸价格明细!K304 -> 0 | M16: =集贸价格明细!M304 -> 0 | N16: =集贸价格明细!K305 -> 0 | O16: =集贸价格明细!M305 -> 0 | P16: =集贸价格明细!K306 -> 0 | Q16: =集贸价格明细!M306 -> -11.7 | R16: =集贸价格明细!K307 -> 0.3 | S16: =集贸价格明细!M307 -> -1.2 | T16: =集贸价格明细!K308 -> 0 | U16: =集贸价格明细!M308 -> -0.8 | V16: =集贸价格明细!K309 -> 0 | W16: =集贸价格明细!M309 -> -0.6
